Workbook

Sheet Read me
B3: Select Appropriate non-billable reason for working days(Mon-Fri) from dropdown in each cell. If working days are blank but allocation on billed code, then will be considered as billable days unless below reason is selected. | E3: Once update is done, pls Mark 'Yes' appropriately 1. This leave tracker 2. Client timesheet if applicable 3. Workday

Sheet Jan'26
E1: To be filled by Ops PMOs only | R1: ---To be filled by Employees---
B2: 1=Working Day | R2: Reason for Non-Billing/Comments | S2: Emp to mark 'Yes' when updated this tracker | T2: Emp to mark 'Yes' when updated the Client timesheet as per this sheet | U2: Emp to mark 'Yes' when updated the Workday as per this sheet | V2: =TEXT(V3,"DDD") -> Thu | W2: =TEXT(W3,"DDD") -> Fri | X2: =TEXT(X3,"DDD") -> Sat | Y2: =TEXT(Y3,"DDD") -> Sun | Z2: =TEXT(Z3,"DDD") -> Mon | AA2: =TEXT(AA3,"DDD") -> Tue | AB2: =TEXT(AB3,"DDD") -> Wed | AC2: =TEXT(AC3,"DDD") -> Thu | ... AZ2: =TEXT(AZ3,"DDD") -> Sat
B3: Emp Id | C3: Emp Name | D3: Emp Client ID | E3: Fractal Email ID | F3: Client email ID | G3: Allocation Start Date | H3: Allocation End Date | I3: Alloc % | J3: Allocated Days | K3: Billed Days for current month | L3: Adj for past month | M3: Revenue cnf days | N3: Timesheet days | O3: Diff | P3: Unbilled Days | Q3: Leaves | V3: 46023 | W3: =V3+1 -> 46024 | X3: =W3+1 -> 46025 | Y3: =X3+1 -> 46026 | Z3: =Y3+1 -> 46027 | AA3: =Z3+1 -> 46028 | AB3: =AA3+1 -> 46029 | AC3: =AB3+1 -> 46030 | AD3: =AC3+1 -> 46031 | ... AZ3: =AY3+1 -> 46053
B4: 1 | C4: =D4+1 -> 3 | D4: =B4+1 -> 2 | E4: =C4+1 -> 4 | F4: =E4+1 -> 5 | G4: =F4+1 -> 6 | H4: =G4+1 -> 7 | I4: =H4+1 -> 8 | J4: =I4+1 -> 9 | K4: =J4+1 -> 10 | L4: =K4+1 -> 11 | M4: =L4+1 -> 12 | ... P4: =O4+1 -> 15 | R4: =P4+1 -> 16 | S4: =R4+1 -> 17 | T4: =S4+1 -> 18 | U4: =T4+1 -> 19 | V4: =U4+1 -> 20 | W4: =V4+1 -> 21 | X4: =W4+1 -> 22 | Y4: =X4+1 -> 23 | Z4: =Y4+1 -> 24 | ... AZ4: =AY4+1 -> 50
B5: F10572 | C5: Aakash Arora | E5: aakash.arora@fractal.ai | G5: 46023 | H5: 46053 | I5: 100 | J5: =NETWORKDAYS(G5,H5)*I5% -> 22 | K5: =J5-COUNTIF(V5:AZ5,"L")-COUNTIF(V5:AZ5,"H")-COUNTIF(V5:AZ5,"HDL")/2-COUNTIF(V5:AZ5,"NB") -> 19 | M5: =SUM(K5:L5) -> 19 | O5: =K5-N5 -> 19 | P5: =J5-K5 -> 3 | Q5: =COUNTIF(V5:BF5,"L")+COUNTIF(V5:BF5,"HDL")/2 -> 0 | S5: Yes | T5: Yes | U5: Yes | V5: H | AJ5: H | AU5: H
B6: F12020 | C6: Aashish Kaushik | E6: aashish.kaushik@fractal.ai | G6: 46023 | H6: 46053 | I6: 100 | J6: =NETWORKDAYS(G6,H6)*I6% -> 22 | K6: =J6-COUNTIF(V6:AZ6,"L")-COUNTIF(V6:AZ6,"H")-COUNTIF(V6:AZ6,"HDL")/2-COUNTIF(V6:AZ6,"NB") -> 18 | M6: =SUM(K6:L6) -> 18 | O6: =K6-N6 -> 18 | P6: =J6-K6 -> 4 | Q6: =COUNTIF(V6:BF6,"L")+COUNTIF(V6:BF6,"HDL")/2 -> 1 | S6: Yes | T6: No | U6: No | V6: H | AG6: L | AJ6: H | AU6: H
B7: F16244 | C7: Abhishek Kumar | E7: abhishek.kumar7@fractal.ai | G7: 46023 | H7: 46053 | I7: 100 | J7: =NETWORKDAYS(G7,H7)*I7% -> 22 | K7: =J7-COUNTIF(V7:AZ7,"L")-COUNTIF(V7:AZ7,"H")-COUNTIF(V7:AZ7,"HDL")/2-COUNTIF(V7:AZ7,"NB") -> 19 | M7: =SUM(K7:L7) -> 19 | O7: =K7-N7 -> 19 | P7: =J7-K7 -> 3 | Q7: =COUNTIF(V7:BF7,"L")+COUNTIF(V7:BF7,"HDL")/2 -> 0 | S7: Yes | T7: Yes | U7: Yes | V7: H | AJ7: H | AU7: H
B8: F17557 | C8: Adithya Udupa | E8: adithya.udupa@fractal.ai | G8: 46023 | H8: 46053 | I8: 100 | J8: =NETWORKDAYS(G8,H8)*I8% -> 22 | K8: =J8-COUNTIF(V8:AZ8,"L")-COUNTIF(V8:AZ8,"H")-COUNTIF(V8:AZ8,"HDL")/2-COUNTIF(V8:AZ8,"NB") -> 18 | M8: =SUM(K8:L8) -> 18 | O8: =K8-N8 -> 18 | P8: =J8-K8 -> 4 | Q8: =COUNTIF(V8:BF8,"L")+COUNTIF(V8:BF8,"HDL")/2 -> 1 | S8: Yes | T8: Yes | U8: No | V8: H | W8: L | AJ8: H | AU8: H
B9: F13935 | C9: Akash Badarinath | E9: akash.badarinath@fractal.ai | G9: 46023 | H9: 46053 | I9: 100 | J9: =NETWORKDAYS(G9,H9)*I9% -> 22 | K9: =J9-COUNTIF(V9:AZ9,"L")-COUNTIF(V9:AZ9,"H")-COUNTIF(V9:AZ9,"HDL")/2-COUNTIF(V9:AZ9,"NB") -> 16 | M9: =SUM(K9:L9) -> 16 | O9: =K9-N9 -> 16 | P9: =J9-K9 -> 6 | Q9: =COUNTIF(V9:BF9,"L")+COUNTIF(V9:BF9,"HDL")/2 -> 2 | S9: Yes | T9: Yes | U9: Yes | V9: H | W9: NB | AI9: H | AU9: H | AV9: L | AW9: L
B10: F15043 | C10: Akash Srivastava | E10: akash.srivastava@fractal.ai | G10: 46023 | H10: 46053 | I10: 100 | J10: =NETWORKDAYS(G10,H10)*I10% -> 22 | K10: =J10-COUNTIF(V10:AZ10,"L")-COUNTIF(V10:AZ10,"H")-COUNTIF(V10:AZ10,"HDL")/2-COUNTIF(V10:AZ10,"NB") -> 18 | M10: =SUM(K10:L10) -> 18 | O10: =K10-N10 -> 18 | P10: =J10-K10 -> 4 | Q10: =COUNTIF(V10:BF10,"L")+COUNTIF(V10:BF10,"HDL")/2 -> 0 | S10: Yes | T10: Yes | U10: Yes | V10: H | W10: NB | AI10: H | AU10: H
B11: F15089 | C11: Amal K | E11: amal.k@fractal.ai | G11: 46023 | H11: 46053 | I11: 100 | J11: =NETWORKDAYS(G11,H11)*I11% -> 22 | K11: =J11-COUNTIF(V11:AZ11,"L")-COUNTIF(V11:AZ11,"H")-COUNTIF(V11:AZ11,"HDL")/2-COUNTIF(V11:AZ11,"NB") -> 0 | M11: =SUM(K11:L11) -> 0 | O11: =K11-N11 -> 0 | P11: =J11-K11 -> 22 | Q11: =COUNTIF(V11:BF11,"L")+COUNTIF(V11:BF11,"HDL")/2 -> 0 | S11: Yes | T11: No | U11: Yes | V11: H | W11: NB | Z11: NB | AA11: NB | AB11: NB | AC11: NB | AD11: NB | AG11: NB | AH11: NB | AI11: NB | AJ11: H | AK11: NB | AN11: NB | AO11: NB | AP11: NB | AQ11: NB | AR11: NB | AU11: H | AV11: NB | AW11: NB | AX11: NB | AY11: NB
B12: F15418 | C12: Ankit . | E12: ankit.1@fractal.ai | G12: 46023 | H12: 46053 | I12: 100 | J12: =NETWORKDAYS(G12,H12)*I12% -> 22 | K12: =J12-COUNTIF(V12:AZ12,"L")-COUNTIF(V12:AZ12,"H")-COUNTIF(V12:AZ12,"HDL")/2-COUNTIF(V12:AZ12,"NB") -> 16 | M12: =SUM(K12:L12) -> 16 | O12: =K12-N12 -> 16 | P12: =J12-K12 -> 6 | Q12: =COUNTIF(V12:BF12,"L")+COUNTIF(V12:BF12,"HDL")/2 -> 2 | S12: Yes | T12: Yes | U12: No | V12: H | W12: NB | AC12: L | AD12: L | AI12: H | AU12: H
B13: F15194 | C13: Ankit Khandelwal | E13: ankit.khandelwal@fractal.ai | G13: 46023 | H13: 46053 | I13: 100 | J13: =NETWORKDAYS(G13,H13)*I13% -> 22 | K13: =J13-COUNTIF(V13:AZ13,"L")-COUNTIF(V13:AZ13,"H")-COUNTIF(V13:AZ13,"HDL")/2-COUNTIF(V13:AZ13,"NB") -> 17 | M13: =SUM(K13:L13) -> 17 | O13: =K13-N13 -> 17 | P13: =J13-K13 -> 5 | Q13: =COUNTIF(V13:BF13,"L")+COUNTIF(V13:BF13,"HDL")/2 -> 1 | S13: Yes | T13: Yes | U13: Yes | V13: H | W13: NB | AI13: L | AJ13: H | AU13: H
B14: F16266 | C14: Anupam Kumar Tiwari | E14: anupam.tiwari@fractal.ai | G14: 46023 | H14: 46053 | I14: 100 | J14: =NETWORKDAYS(G14,H14)*I14% -> 22 | K14: =J14-COUNTIF(V14:AZ14,"L")-COUNTIF(V14:AZ14,"H")-COUNTIF(V14:AZ14,"HDL")/2-COUNTIF(V14:AZ14,"NB") -> 15 | M14: =SUM(K14:L14) -> 15 | O14: =K14-N14 -> 15 | P14: =J14-K14 -> 7 | Q14: =COUNTIF(V14:BF14,"L")+COUNTIF(V14:BF14,"HDL")/2 -> 4 | S14: Yes | T14: Yes | U14: Yes | V14: H | AG14: L | AJ14: H | AN14: L | AO14: L | AU14: H | AV14: L
B15: F17311 | C15: Arbaz Ur Rehman Khan | E15: arbazur.khan@fractal.ai | G15: 46023 | H15: 46053 | I15: 100 | J15: =NETWORKDAYS(G15,H15)*I15% -> 22 | K15: =J15-COUNTIF(V15:AZ15,"L")-COUNTIF(V15:AZ15,"H")-COUNTIF(V15:AZ15,"HDL")/2-COUNTIF(V15:AZ15,"NB") -> 18 | M15: =SUM(K15:L15) -> 18 | O15: =K15-N15 -> 18 | P15: =J15-K15 -> 4 | Q15: =COUNTIF(V15:BF15,"L")+COUNTIF(V15:BF15,"HDL")/2 -> 0 | S15: Yes | T15: Yes | U15: Yes | V15: H | W15: NB | AJ15: H | AU15: H
B16: F15984 | C16: Arindom Goswami | E16: arindom.goswami@fractal.ai | G16: 46023 | H16: 46053 | I16: 100 | J16: =NETWORKDAYS(G16,H16)*I16% -> 22 | K16: =J16-COUNTIF(V16:AZ16,"L")-COUNTIF(V16:AZ16,"H")-COUNTIF(V16:AZ16,"HDL")/2-COUNTIF(V16:AZ16,"NB") -> 18 | M16: =SUM(K16:L16) -> 18 | O16: =K16-N16 -> 18 | P16: =J16-K16 -> 4 | Q16: =COUNTIF(V16:BF16,"L")+COUNTIF(V16:BF16,"HDL")/2 -> 1 | S16: Yes | T16: Yes | U16: Yes | V16: H | AA16: L | AJ16: H | AU16: H
B17: F07920 | C17: Arjit Sharma | E17: arjit.sharma@fractal.ai | G17: 46023 | H17: 46053 | I17: 100 | J17: =NETWORKDAYS(G17,H17)*I17% -> 22 | K17: =J17-COUNTIF(V17:AZ17,"L")-COUNTIF(V17:AZ17,"H")-COUNTIF(V17:AZ17,"HDL")/2-COUNTIF(V17:AZ17,"NB") -> 18 | M17: =SUM(K17:L17) -> 18 | O17: =K17-N17 -> 18 | P17: =J17-K17 -> 4 | Q17: =COUNTIF(V17:BF17,"L")+COUNTIF(V17:BF17,"HDL")/2 -> 0 | S17: Yes | T17: Yes | U17: No | V17: H | W17: NB | AI17: H | AU17: H
B18: F08462 | C18: Ashokkumar Subramani | E18: ashokkumar.subramani@fractal.ai | G18: 46023 | H18: 46053 | I18: 100 | J18: =NETWORKDAYS(G18,H18)*I18% -> 22 | K18: =J18-COUNTIF(V18:AZ18,"L")-COUNTIF(V18:AZ18,"H")-COUNTIF(V18:AZ18,"HDL")/2-COUNTIF(V18:AZ18,"NB") -> 18 | M18: =SUM(K18:L18) -> 18 | O18: =K18-N18 -> 18 | P18: =J18-K18 -> 4 | Q18: =COUNTIF(V18:BF18,"L")+COUNTIF(V18:BF18,"HDL")/2 -> 0 | S18: Yes | T18: Yes | U18: No | V18: H | W18: NB | AI18: H | AU18: H
B19: F07471 | C19: Avinash . | E19: avinash.1@fractal.ai | G19: 46023 | H19: 46053 | I19: 100 | J19: =NETWORKDAYS(G19,H19)*I19% -> 22 | K19: =J19-COUNTIF(V19:AZ19,"L")-COUNTIF(V19:AZ19,"H")-COUNTIF(V19:AZ19,"HDL")/2-COUNTIF(V19:AZ19,"NB") -> 19 | M19: =SUM(K19:L19) -> 19 | O19: =K19-N19 -> 19 | P19: =J19-K19 -> 3 | Q19: =COUNTIF(V19:BF19,"L")+COUNTIF(V19:BF19,"HDL")/2 -> 0 | S19: Yes | T19: Yes | U19: Yes | V19: H | AJ19: H | AU19: H
B20: F17726 | C20: Bhanu Priya | E20: bhanu.priya2@fractal.ai | G20: 46023 | H20: 46053 | I20: 100 | J20: =NETWORKDAYS(G20,H20)*I20% -> 22 | K20: =J20-COUNTIF(V20:AZ20,"L")-COUNTIF(V20:AZ20,"H")-COUNTIF(V20:AZ20,"HDL")/2-COUNTIF(V20:AZ20,"NB") -> 16 | M20: =SUM(K20:L20) -> 16 | O20: =K20-N20 -> 16 | P20: =J20-K20 -> 6 | Q20: =COUNTIF(V20:BF20,"L")+COUNTIF(V20:BF20,"HDL")/2 -> 4 | S20: Yes | T20: No | U20: No | V20: H | W20: L | AI20: L | AJ20: H | AK20: L | AY20: L
B21: F05022 | C21: Chaitanya Deepak | E21: chaitanya.deepak@fractal.ai | G21: 46023 | H21: 46053 | I21: 100 | J21: =NETWORKDAYS(G21,H21)*I21% -> 22 | K21: =J21-COUNTIF(V21:AZ21,"L")-COUNTIF(V21:AZ21,"H")-COUNTIF(V21:AZ21,"HDL")/2-COUNTIF(V21:AZ21,"NB") -> 17 | M21: =SUM(K21:L21) -> 17 | O21: =K21-N21 -> 17 | P21: =J21-K21 -> 5 | Q21: =COUNTIF(V21:BF21,"L")+COUNTIF(V21:BF21,"HDL")/2 -> 2 | S21: Yes | T21: Yes | U21: Yes | V21: H | AB21: L | AJ21: H | AU21: H | AY21: L
B22: F14094 | C22: Gokul Vasanth Susindran | E22: gokul.susindran@fractal.ai | G22: 46023 | H22: 46053 | I22: 100 | J22: =NETWORKDAYS(G22,H22)*I22% -> 22 | K22: =J22-COUNTIF(V22:AZ22,"L")-COUNTIF(V22:AZ22,"H")-COUNTIF(V22:AZ22,"HDL")/2-COUNTIF(V22:AZ22,"NB") -> 17 | M22: =SUM(K22:L22) -> 17 | O22: =K22-N22 -> 17 | P22: =J22-K22 -> 5 | Q22: =COUNTIF(V22:BF22,"L")+COUNTIF(V22:BF22,"HDL")/2 -> 1 | S22: Yes | T22: Yes | U22: Yes | V22: H | W22: NB | AG22: L | AI22: H | AU22: H
B23: F09402 | C23: Gowtham G | E23: gowtham.g@fractal.ai | G23: 46023 | H23: 46053 | I23: 100 | J23: =NETWORKDAYS(G23,H23)*I23% -> 22 | K23: =J23-COUNTIF(V23:AZ23,"L")-COUNTIF(V23:AZ23,"H")-COUNTIF(V23:AZ23,"HDL")/2-COUNTIF(V23:AZ23,"NB") -> 17 | M23: =SUM(K23:L23) -> 17 | O23: =K23-N23 -> 17 | P23: =J23-K23 -> 5 | Q23: =COUNTIF(V23:BF23,"L")+COUNTIF(V23:BF23,"HDL")/2 -> 2 | S23: Yes | T23: No | U23: No | V23: H | AI23: H | AJ23: L | AU23: H | AW23: L
B24: F08055 | C24: K Deepak | E24: k.deepak@fractal.ai | G24: 46023 | H24: 46053 | I24: 100 | J24: =NETWORKDAYS(G24,H24)*I24% -> 22 | K24: =J24-COUNTIF(V24:AZ24,"L")-COUNTIF(V24:AZ24,"H")-COUNTIF(V24:AZ24,"HDL")/2-COUNTIF(V24:AZ24,"NB") -> 17 | M24: =SUM(K24:L24) -> 17 | O24: =K24-N24 -> 17 | P24: =J24-K24 -> 5 | Q24: =COUNTIF(V24:BF24,"L")+COUNTIF(V24:BF24,"HDL")/2 -> 1 | S24: Yes | T24: yes | U24: yes | V24: H | W24: NB | AJ24: H | AK24: L | AU24: H
B25: F15951 | C25: Kesani Srichandana | E25: kesani.srichandana@fractal.ai | G25: 46023 | H25: 46053 | I25: 100 | J25: =NETWORKDAYS(G25,H25)*I25% -> 22 | K25: =J25-COUNTIF(V25:AZ25,"L")-COUNTIF(V25:AZ25,"H")-COUNTIF(V25:AZ25,"HDL")/2-COUNTIF(V25:AZ25,"NB") -> 18.5 | M25: =SUM(K25:L25) -> 18.5 | O25: =K25-N25 -> 18.5 | P25: =J25-K25 -> 3.5 | Q25: =COUNTIF(V25:BF25,"L")+COUNTIF(V25:BF25,"HDL")/2 -> 0.5 | S25: Yes | T25: Yes | U25: Yes | V25: H | AJ25: H | AK25: HDL | AU25: H
B26: F16291 | C26: Khasim Pannegatla | E26: khasim.pannegatla@fractal.ai | G26: 46023 | H26: 46053 | I26: 100 | J26: =NETWORKDAYS(G26,H26)*I26% -> 22 | K26: =J26-COUNTIF(V26:AZ26,"L")-COUNTIF(V26:AZ26,"H")-COUNTIF(V26:AZ26,"HDL")/2-COUNTIF(V26:AZ26,"NB") -> 18 | M26: =SUM(K26:L26) -> 18 | O26: =K26-N26 -> 18 | P26: =J26-K26 -> 4 | Q26: =COUNTIF(V26:BF26,"L")+COUNTIF(V26:BF26,"HDL")/2 -> 1 | S26: Yes | T26: Yes | U26: Yes | V26: H | W26: L | AJ26: H | AU26: H
B27: F16247 | C27: Kiran Mai P | E27: kiran.p@fractal.ai | G27: 46023 | H27: 46053 | I27: 100 | J27: =NETWORKDAYS(G27,H27)*I27% -> 22 | K27: =J27-COUNTIF(V27:AZ27,"L")-COUNTIF(V27:AZ27,"H")-COUNTIF(V27:AZ27,"HDL")/2-COUNTIF(V27:AZ27,"NB") -> 16 | M27: =SUM(K27:L27) -> 16 | O27: =K27-N27 -> 16 | P27: =J27-K27 -> 6 | Q27: =COUNTIF(V27:BF27,"L")+COUNTIF(V27:BF27,"HDL")/2 -> 3 | R27: 29th leave was missed | S27: Yes | T27: No | U27: yes | V27: H | AH27: L | AI27: L | AJ27: H | AU27: H | AX27: L
B28: F12415 | C28: Kunal Kumar | E28: kunal.kumar@fractal.ai | G28: 46023 | H28: 46053 | I28: 100 | J28: =NETWORKDAYS(G28,H28)*I28% -> 22 | K28: =J28-COUNTIF(V28:AZ28,"L")-COUNTIF(V28:AZ28,"H")-COUNTIF(V28:AZ28,"HDL")/2-COUNTIF(V28:AZ28,"NB") -> 4 | M28: =SUM(K28:L28) -> 4 | O28: =K28-N28 -> 4 | P28: =J28-K28 -> 18 | Q28: =COUNTIF(V28:BF28,"L")+COUNTIF(V28:BF28,"HDL")/2 -> 15 | S28: Yes | T28: Yes | U28: No | V28: H | W28: L | Z28: L | AA28: L | AB28: L | AC28: L | AD28: L | AG28: L | AH28: L | AI28: H | AJ28: L | AK28: L | AN28: L | AO28: L | AP28: L | AQ28: L | AR28: L | AU28: H
B29: F12766 | C29: Madhavi Latha Kotturu | E29: madhavilatha.kotturu@fractal.ai | G29: 46023 | H29: 46053 | I29: 100 | J29: =NETWORKDAYS(G29,H29)*I29% -> 22 | K29: =J29-COUNTIF(V29:AZ29,"L")-COUNTIF(V29:AZ29,"H")-COUNTIF(V29:AZ29,"HDL")/2-COUNTIF(V29:AZ29,"NB") -> 18 | M29: =SUM(K29:L29) -> 18 | O29: =K29-N29 -> 18 | P29: =J29-K29 -> 4 | Q29: =COUNTIF(V29:BF29,"L")+COUNTIF(V29:BF29,"HDL")/2 -> 1 | R29: 2nd jan leave was missed | S29: yes | T29: yes | U29: yes | V29: H | W29: L | AJ29: H | AU29: H
B30: F06490 | C30: Mahamad Asif | E30: mahamad.asif@fractal.ai | G30: 46023 | H30: 46053 | I30: 100 | J30: =NETWORKDAYS(G30,H30)*I30% -> 22 | K30: =J30-COUNTIF(V30:AZ30,"L")-COUNTIF(V30:AZ30,"H")-COUNTIF(V30:AZ30,"HDL")/2-COUNTIF(V30:AZ30,"NB") -> 17 | M30: =SUM(K30:L30) -> 17 | O30: =K30-N30 -> 17 | P30: =J30-K30 -> 5 | Q30: =COUNTIF(V30:BF30,"L")+COUNTIF(V30:BF30,"HDL")/2 -> 1 | S30: Yes | T30: Yes | U30: Yes | V30: H | W30: NB | AJ30: H | AK30: L | AU30: H
B31: F16307 | C31: Mallik Saptarshi Thakur | E31: mallik.thakur@fractal.ai | G31: 46023 | H31: 46053 | I31: 100 | J31: =NETWORKDAYS(G31,H31)*I31% -> 22 | K31: =J31-COUNTIF(V31:AZ31,"L")-COUNTIF(V31:AZ31,"H")-COUNTIF(V31:AZ31,"HDL")/2-COUNTIF(V31:AZ31,"NB") -> 18 | M31: =SUM(K31:L31) -> 18 | O31: =K31-N31 -> 18 | P31: =J31-K31 -> 4 | Q31: =COUNTIF(V31:BF31,"L")+COUNTIF(V31:BF31,"HDL")/2 -> 1 | S31: yes | T31: yes | U31: yes | V31: H | W31: L | AI31: H | AU31: H
B32: F14195 | C32: Manish Khare | E32: manish.khare@fractal.ai | G32: 46023 | H32: 46053 | I32: 100 | J32: =NETWORKDAYS(G32,H32)*I32% -> 22 | K32: =J32-COUNTIF(V32:AZ32,"L")-COUNTIF(V32:AZ32,"H")-COUNTIF(V32:AZ32,"HDL")/2-COUNTIF(V32:AZ32,"NB") -> 18 | M32: =SUM(K32:L32) -> 18 | O32: =K32-N32 -> 18 | P32: =J32-K32 -> 4 | Q32: =COUNTIF(V32:BF32,"L")+COUNTIF(V32:BF32,"HDL")/2 -> 1 | S32: Yes | T32: Yes | U32: Yes | V32: H | W32: L | AI32: H | AU32: H
B33: F16444 | C33: Manish Rajesh Sharma | E33: manish.sharma@fractal.ai | G33: 46023 | H33: 46053 | I33: 100 | J33: =NETWORKDAYS(G33,H33)*I33% -> 22 | K33: =J33-COUNTIF(V33:AZ33,"L")-COUNTIF(V33:AZ33,"H")-COUNTIF(V33:AZ33,"HDL")/2-COUNTIF(V33:AZ33,"NB") -> 18 | M33: =SUM(K33:L33) -> 18 | O33: =K33-N33 -> 18 | P33: =J33-K33 -> 4 | Q33: =COUNTIF(V33:BF33,"L")+COUNTIF(V33:BF33,"HDL")/2 -> 0 | R33: Holiday updated | S33: Yes | T33: Yes | U33: Yes | V33: H | W33: NB | AI33: H | AU33: H
B34: F13899 | C34: Muhammed Suhail E K | E34: muhammed.suhail@fractal.ai | G34: 46023 | H34: 46053 | I34: 100 | J34: =NETWORKDAYS(G34,H34)*I34% -> 22 | K34: =J34-COUNTIF(V34:AZ34,"L")-COUNTIF(V34:AZ34,"H")-COUNTIF(V34:AZ34,"HDL")/2-COUNTIF(V34:AZ34,"NB") -> 17 | M34: =SUM(K34:L34) -> 17 | O34: =K34-N34 -> 17 | P34: =J34-K34 -> 5 | Q34: =COUNTIF(V34:BF34,"L")+COUNTIF(V34:BF34,"HDL")/2 -> 2 | S34: Yes | T34: Yes | U34: Yes | V34: H | AI34: H | AU34: H | AV34: L | AW34: L
B35: F13753 | C35: Nagarjun K | E35: nagarjun.k@fractal.ai | G35: 46023 | H35: 46053 | I35: 100 | J35: =NETWORKDAYS(G35,H35)*I35% -> 22 | K35: =J35-COUNTIF(V35:AZ35,"L")-COUNTIF(V35:AZ35,"H")-COUNTIF(V35:AZ35,"HDL")/2-COUNTIF(V35:AZ35,"NB") -> 18 | M35: =SUM(K35:L35) -> 18 | O35: =K35-N35 -> 18 | P35: =J35-K35 -> 4 | Q35: =COUNTIF(V35:BF35,"L")+COUNTIF(V35:BF35,"HDL")/2 -> 0 | S35: Yes | T35: Yes | U35: Yes | V35: H | W35: NB | AI35: H | AU35: H
B36: F14646 | C36: Nihar Bastia | E36: nihar.bastia@fractal.ai | G36: 46023 | H36: 46053 | I36: 100 | J36: =NETWORKDAYS(G36,H36)*I36% -> 22 | K36: =J36-COUNTIF(V36:AZ36,"L")-COUNTIF(V36:AZ36,"H")-COUNTIF(V36:AZ36,"HDL")/2-COUNTIF(V36:AZ36,"NB") -> 16 | M36: =SUM(K36:L36) -> 16 | O36: =K36-N36 -> 16 | P36: =J36-K36 -> 6 | Q36: =COUNTIF(V36:BF36,"L")+COUNTIF(V36:BF36,"HDL")/2 -> 2 | S36: Yes | T36: Yes | U36: Yes | V36: H | W36: NB | AH36: L | AI36: H | AN36: L | AU36: H
B37: F11421 | C37: Pavan Kumar Reddy Tondapu | E37: pavankumarreddy.tondapu@fractal.ai | G37: 46023 | H37: 46053 | I37: 100 | J37: =NETWORKDAYS(G37,H37)*I37% -> 22 | K37: =J37-COUNTIF(V37:AZ37,"L")-COUNTIF(V37:AZ37,"H")-COUNTIF(V37:AZ37,"HDL")/2-COUNTIF(V37:AZ37,"NB") -> 16 | M37: =SUM(K37:L37) -> 16 | O37: =K37-N37 -> 16 | P37: =J37-K37 -> 6 | Q37: =COUNTIF(V37:BF37,"L")+COUNTIF(V37:BF37,"HDL")/2 -> 2 | S37: Yes | T37: Yes | U37: Yes | V37: H | W37: NB | AI37: L | AJ37: H | AK37: L | AU37: H
B38: F09792 | C38: Pinninti Ravindra | E38: pinninti.ravindra@fractal.ai | G38: 46023 | H38: 46053 | I38: 100 | J38: =NETWORKDAYS(G38,H38)*I38% -> 22 | K38: =J38-COUNTIF(V38:AZ38,"L")-COUNTIF(V38:AZ38,"H")-COUNTIF(V38:AZ38,"HDL")/2-COUNTIF(V38:AZ38,"NB") -> 14 | M38: =SUM(K38:L38) -> 14 | O38: =K38-N38 -> 14 | P38: =J38-K38 -> 8 | Q38: =COUNTIF(V38:BF38,"L")+COUNTIF(V38:BF38,"HDL")/2 -> 4 | S38: yes | T38: No | U38: No | V38: H | W38: NB | AD38: L | AI38: L | AJ38: H | AK38: L | AU38: H | AV38: L
B39: F15834 | C39: Prajwal Athrey | E39: prajwal.athrey@fractal.ai | G39: 46023 | H39: 46053 | I39: 100 | J39: =NETWORKDAYS(G39,H39)*I39% -> 22 | K39: =J39-COUNTIF(V39:AZ39,"L")-COUNTIF(V39:AZ39,"H")-COUNTIF(V39:AZ39,"HDL")/2-COUNTIF(V39:AZ39,"NB") -> 15 | M39: =SUM(K39:L39) -> 15 | O39: =K39-N39 -> 15 | P39: =J39-K39 -> 7 | Q39: =COUNTIF(V39:BF39,"L")+COUNTIF(V39:BF39,"HDL")/2 -> 3 | S39: Yes | T39: Yes | U39: Yes | V39: H | W39: NB | AA39: L | AJ39: H | AK39: L | AN39: L | AU39: H
B40: F14085 | C40: Prakash Solanki | E40: prakash.solanki@fractal.ai | G40: 46023 | H40: 46053 | I40: 100 | J40: =NETWORKDAYS(G40,H40)*I40% -> 22 | K40: =J40-COUNTIF(V40:AZ40,"L")-COUNTIF(V40:AZ40,"H")-COUNTIF(V40:AZ40,"HDL")/2-COUNTIF(V40:AZ40,"NB") -> 18 | M40: =SUM(K40:L40) -> 18 | O40: =K40-N40 -> 18 | P40: =J40-K40 -> 4 | Q40: =COUNTIF(V40:BF40,"L")+COUNTIF(V40:BF40,"HDL")/2 -> 0 | S40: Yes | T40: Yes | U40: Yes | V40: H | W40: NB | AJ40: H | AU40: H
...

Sheet Sheet2
A1: Employee Code | B1: Employee Name | C1: 46023
A2: F02721 | B2: Ratul Ramchandani | C2: 1 | F2: =_xlfn.XLOOKUP(A2,'Jan''26'!B:B,'Jan''26'!Q:Q,0,0,1) -> 2
A3: F06490 | B3: Mahamad Asif | C3: 1 | F3: =_xlfn.XLOOKUP(A3,'Jan''26'!B:B,'Jan''26'!Q:Q,0,0,1) -> 1
A4: F07471 | B4: Avinash . | C4: 0 | F4: =_xlfn.XLOOKUP(A4,'Jan''26'!B:B,'Jan''26'!Q:Q,0,0,1) -> 0
A5: F07920 | B5: Arjit Sharma | C5: 0 | F5: =_xlfn.XLOOKUP(A5,'Jan''26'!B:B,'Jan''26'!Q:Q,0,0,1) -> 0
A6: F08227 | B6: Shubham Bhaskar | C6: 1 | F6: =_xlfn.XLOOKUP(A6,'Jan''26'!B:B,'Jan''26'!Q:Q,0,0,1) -> 1
A7: F08462 | B7: Ashokkumar Subramani | C7: 0 | F7: =_xlfn.XLOOKUP(A7,'Jan''26'!B:B,'Jan''26'!Q:Q,0,0,1) -> 0
A8: F09402 | B8: Gowtham G | C8: 2 | F8: =_xlfn.XLOOKUP(A8,'Jan''26'!B:B,'Jan''26'!Q:Q,0,0,1) -> 2
A9: F09515 | B9: Roshan Raghavendra Srinivas | C9: 2 | F9: =_xlfn.XLOOKUP(A9,'Jan''26'!B:B,'Jan''26'!Q:Q,0,0,1) -> 2
A10: F09792 | B10: Pinninti Ravindra | C10: 4 | F10: =_xlfn.XLOOKUP(A10,'Jan''26'!B:B,'Jan''26'!Q:Q,0,0,1) -> 4
A11: F10572 | B11: Aakash Arora | C11: 0 | F11: =_xlfn.XLOOKUP(A11,'Jan''26'!B:B,'Jan''26'!Q:Q,0,0,1) -> 0
A12: F11421 | B12: Pavan Kumar Reddy Tondapu | C12: 2 | F12: =_xlfn.XLOOKUP(A12,'Jan''26'!B:B,'Jan''26'!Q:Q,0,0,1) -> 2
A13: F12020 | B13: Aashish Kaushik | C13: 1 | F13: =_xlfn.XLOOKUP(A13,'Jan''26'!B:B,'Jan''26'!Q:Q,0,0,1) -> 1
... A32: F17726 | B32: Bhanu Priya | C32: 4 | F32: =_xlfn.XLOOKUP(A32,'Jan''26'!B:B,'Jan''26'!Q:Q,0,0,1) -> 4
A33: F16221 | B33: Dijal Tom | F33: =_xlfn.XLOOKUP(A33,'Jan''26'!B:B,'Jan''26'!Q:Q,0,0,1) -> 0
A34: F17891 | B34: Hithesh G R | F34: =_xlfn.XLOOKUP(A34,'Jan''26'!B:B,'Jan''26'!Q:Q,0,0,1) -> 0
A35: F11776 | B35: Neha Agrawal | F35: =_xlfn.XLOOKUP(A35,'Jan''26'!B:B,'Jan''26'!Q:Q,0,0,1) -> 0

Sheet Feb'26
E1: To be filled by Ops PMOs only | R1: ---To be filled by Employees---
B2: 1=Working Day | R2: Reason for Non-Billing/Comments | S2: Emp to mark 'Yes' when updated this tracker | T2: Emp to mark 'Yes' when updated the Client timesheet as per this sheet | U2: Emp to mark 'Yes' when updated the Workday as per this sheet | V2: =TEXT(V3,"DDD") -> Sun | W2: =TEXT(W3,"DDD") -> Mon | X2: =TEXT(X3,"DDD") -> Tue | Y2: =TEXT(Y3,"DDD") -> Wed | Z2: =TEXT(Z3,"DDD") -> Thu | AA2: =TEXT(AA3,"DDD") -> Fri | AB2: =TEXT(AB3,"DDD") -> Sat | AC2: =TEXT(AC3,"DDD") -> Sun | ... AW2: =TEXT(AW3,"DDD") -> Sat
B3: Emp Id | C3: Emp Name | D3: Emp Client ID | E3: Fractal Email ID | F3: Client email ID | G3: Allocation Start Date | H3: Allocation End Date | I3: Alloc % | J3: Allocated Days | K3: Billed Days for current month | L3: Adj for past month | M3: Revenue cnf days | N3: Timesheet days | O3: Diff | P3: Unbilled Days | Q3: Total Leave Days | V3: 46054 | W3: =V3+1 -> 46055 | X3: =W3+1 -> 46056 | Y3: =X3+1 -> 46057 | Z3: =Y3+1 -> 46058 | AA3: =Z3+1 -> 46059 | AB3: =AA3+1 -> 46060 | AC3: =AB3+1 -> 46061 | AD3: =AC3+1 -> 46062 | ... AW3: =AV3+1 -> 46081
B4: 1 | C4: =D4+1 -> 3 | D4: =B4+1 -> 2 | E4: =C4+1 -> 4 | F4: =E4+1 -> 5 | G4: =F4+1 -> 6 | H4: =G4+1 -> 7 | I4: =H4+1 -> 8 | J4: =I4+1 -> 9 | K4: =J4+1 -> 10 | L4: =K4+1 -> 11 | M4: =L4+1 -> 12 | ... P4: =O4+1 -> 15 | R4: =P4+1 -> 16 | S4: =R4+1 -> 17 | T4: =S4+1 -> 18 | U4: =T4+1 -> 19 | V4: =U4+1 -> 20 | W4: =V4+1 -> 21 | X4: =W4+1 -> 22 | Y4: =X4+1 -> 23 | Z4: =Y4+1 -> 24 | ... AW4: =AV4+1 -> 47
B5: F10572 | C5: Aakash Arora | G5: 46054 | H5: 46081 | I5: 100 | J5: =NETWORKDAYS(G5,H5)*I5% -> 20 | K5: =J5-COUNTIF(V5:AW5,"L")-COUNTIF(V5:AW5,"H")-COUNTIF(V5:AW5,"HDL")/2-COUNTIF(V5:AW5,"NB") -> 17 | M5: =SUM(K5:L5) -> 17 | O5: =K5-N5 -> 17 | P5: =J5-K5 -> 3 | Q5: =COUNTIF(W5:BF5,"L")+COUNTIF(W5:BF5,"HDL")/2 -> 3 | S5: Yes | T5: NO | U5: Yes | Y5: L | Z5: L | AA5: L
B6: F12020 | C6: Aashish Kaushik | G6: 46054 | H6: 46081 | I6: 100 | J6: =NETWORKDAYS(G6,H6)*I6% -> 20 | K6: =J6-COUNTIF(V6:AW6,"L")-COUNTIF(V6:AW6,"H")-COUNTIF(V6:AW6,"HDL")/2-COUNTIF(V6:AW6,"NB") -> 19 | M6: =SUM(K6:L6) -> 19 | O6: =K6-N6 -> 19 | P6: =J6-K6 -> 1 | Q6: =COUNTIF(W6:BF6,"L")+COUNTIF(W6:BF6,"HDL")/2 -> 1 | S6: Yes | T6: NO | U6: No | AL6: L
B7: F16244 | C7: Abhishek Kumar | G7: 46054 | H7: 46081 | I7: 100 | J7: =NETWORKDAYS(G7,H7)*I7% -> 20 | K7: =J7-COUNTIF(V7:AW7,"L")-COUNTIF(V7:AW7,"H")-COUNTIF(V7:AW7,"HDL")/2-COUNTIF(V7:AW7,"NB") -> 20 | M7: =SUM(K7:L7) -> 20 | O7: =K7-N7 -> 20 | P7: =J7-K7 -> 0 | Q7: =COUNTIF(W7:BF7,"L")+COUNTIF(W7:BF7,"HDL")/2 -> 0 | S7: Yes | T7: Yes | U7: Yes
B8: F17557 | C8: Adithya Udupa | G8: 46054 | H8: 46081 | I8: 100 | J8: =NETWORKDAYS(G8,H8)*I8% -> 20 | K8: =J8-COUNTIF(V8:AW8,"L")-COUNTIF(V8:AW8,"H")-COUNTIF(V8:AW8,"HDL")/2-COUNTIF(V8:AW8,"NB") -> 19 | M8: =SUM(K8:L8) -> 19 | O8: =K8-N8 -> 19 | P8: =J8-K8 -> 1 | Q8: =COUNTIF(W8:BF8,"L")+COUNTIF(W8:BF8,"HDL")/2 -> 1 | S8: Yes | T8: NO | U8: No | AA8: L
B9: F13935 | C9: Akash Badarinath | G9: 46054 | H9: 46081 | I9: 100 | J9: =NETWORKDAYS(G9,H9)*I9% -> 20 | K9: =J9-COUNTIF(V9:AW9,"L")-COUNTIF(V9:AW9,"H")-COUNTIF(V9:AW9,"HDL")/2-COUNTIF(V9:AW9,"NB") -> 15 | M9: =SUM(K9:L9) -> 15 | O9: =K9-N9 -> 15 | P9: =J9-K9 -> 5 | Q9: =COUNTIF(W9:BF9,"L")+COUNTIF(W9:BF9,"HDL")/2 -> 5 | S9: Yes | T9: NO | U9: No | AN9: L | AO9: L | AR9: L | AS9: L | AT9: L
B10: F15043 | C10: Akash Srivastava | G10: 46054 | H10: 46081 | I10: 100 | J10: =NETWORKDAYS(G10,H10)*I10% -> 20 | K10: =J10-COUNTIF(V10:AW10,"L")-COUNTIF(V10:AW10,"H")-COUNTIF(V10:AW10,"HDL")/2-COUNTIF(V10:AW10,"NB") -> 17 | M10: =SUM(K10:L10) -> 17 | O10: =K10-N10 -> 17 | P10: =J10-K10 -> 3 | Q10: =COUNTIF(W10:BF10,"L")+COUNTIF(W10:BF10,"HDL")/2 -> 3 | S10: Yes | T10: Yes | U10: Yes | AA10: L | AG10: L | AH10: L
B11: F15089 | C11: Amal K | G11: 46054 | H11: 46081 | I11: 100 | J11: =NETWORKDAYS(G11,H11)*I11% -> 20 | K11: =J11-COUNTIF(V11:AW11,"L")-COUNTIF(V11:AW11,"H")-COUNTIF(V11:AW11,"HDL")/2-COUNTIF(V11:AW11,"NB") -> 0 | M11: =SUM(K11:L11) -> 0 | O11: =K11-N11 -> 0 | P11: =J11-K11 -> 20 | Q11: =COUNTIF(W11:BF11,"L")+COUNTIF(W11:BF11,"HDL")/2 -> 0 | R11: Allocated to the project, onboarding scheduled for March 2nd. Hence marked as NB. No leaves taken. | S11: yes | T11: NO | U11: yes | W11: NB | X11: NB | Y11: NB | Z11: NB | AA11: NB | AD11: NB | AE11: NB | AF11: NB | AG11: NB | AH11: NB | AK11: NB | AL11: NB | AM11: NB | AN11: NB | AO11: NB | AR11: NB | AS11: NB | AT11: NB | AU11: NB | AV11: NB
B12: F15418 | C12: Ankit . | G12: 46054 | H12: 46081 | I12: 100 | J12: =NETWORKDAYS(G12,H12)*I12% -> 20 | K12: =J12-COUNTIF(V12:AW12,"L")-COUNTIF(V12:AW12,"H")-COUNTIF(V12:AW12,"HDL")/2-COUNTIF(V12:AW12,"NB") -> 20 | M12: =SUM(K12:L12) -> 20 | O12: =K12-N12 -> 20 | P12: =J12-K12 -> 0 | Q12: =COUNTIF(W12:BF12,"L")+COUNTIF(W12:BF12,"HDL")/2 -> 0 | S12: Yes | T12: NO | U12: No
B13: F15194 | C13: Ankit Khandelwal | G13: 46054 | H13: 46081 | I13: 100 | J13: =NETWORKDAYS(G13,H13)*I13% -> 20 | K13: =J13-COUNTIF(V13:AW13,"L")-COUNTIF(V13:AW13,"H")-COUNTIF(V13:AW13,"HDL")/2-COUNTIF(V13:AW13,"NB") -> 20 | M13: =SUM(K13:L13) -> 20 | O13: =K13-N13 -> 20 | P13: =J13-K13 -> 0 | Q13: =COUNTIF(W13:BF13,"L")+COUNTIF(W13:BF13,"HDL")/2 -> 0 | S13: Yes | T13: NO | U13: No
B14: F16266 | C14: Anupam Kumar Tiwari | G14: 46054 | H14: 46081 | I14: 100 | J14: =NETWORKDAYS(G14,H14)*I14% -> 20 | K14: =J14-COUNTIF(V14:AW14,"L")-COUNTIF(V14:AW14,"H")-COUNTIF(V14:AW14,"HDL")/2-COUNTIF(V14:AW14,"NB") -> 19 | M14: =SUM(K14:L14) -> 19 | O14: =K14-N14 -> 19 | P14: =J14-K14 -> 1 | Q14: =COUNTIF(W14:BF14,"L")+COUNTIF(W14:BF14,"HDL")/2 -> 1 | S14: Yes | T14: NO | U14: No | AM14: L
B15: F17311 | C15: Arbaz Ur Rehman Khan | G15: 46054 | H15: 46081 | I15: 100 | J15: =NETWORKDAYS(G15,H15)*I15% -> 20 | K15: =J15-COUNTIF(V15:AW15,"L")-COUNTIF(V15:AW15,"H")-COUNTIF(V15:AW15,"HDL")/2-COUNTIF(V15:AW15,"NB") -> 20 | M15: =SUM(K15:L15) -> 20 | O15: =K15-N15 -> 20 | P15: =J15-K15 -> 0 | Q15: =COUNTIF(W15:BF15,"L")+COUNTIF(W15:BF15,"HDL")/2 -> 0 | S15: Yes | T15: NO | U15: Yes
B16: F15984 | C16: Arindom Goswami | G16: 46054 | H16: 46081 | I16: 100 | J16: =NETWORKDAYS(G16,H16)*I16% -> 20 | K16: =J16-COUNTIF(V16:AW16,"L")-COUNTIF(V16:AW16,"H")-COUNTIF(V16:AW16,"HDL")/2-COUNTIF(V16:AW16,"NB") -> 19 | M16: =SUM(K16:L16) -> 19 | O16: =K16-N16 -> 19 | P16: =J16-K16 -> 1 | Q16: =COUNTIF(W16:BF16,"L")+COUNTIF(W16:BF16,"HDL")/2 -> 1 | S16: Yes | T16: Yes | U16: Yes | AK16: L
B17: F07920 | C17: Arjit Sharma | G17: 46054 | H17: 46081 | I17: 100 | J17: =NETWORKDAYS(G17,H17)*I17% -> 20 | K17: =J17-COUNTIF(V17:AW17,"L")-COUNTIF(V17:AW17,"H")-COUNTIF(V17:AW17,"HDL")/2-COUNTIF(V17:AW17,"NB") -> 18 | M17: =SUM(K17:L17) -> 18 | O17: =K17-N17 -> 18 | P17: =J17-K17 -> 2 | Q17: =COUNTIF(W17:BF17,"L")+COUNTIF(W17:BF17,"HDL")/2 -> 2 | S17: Yes | T17: NO | U17: No | AH17: L | AK17: L
B18: F08462 | C18: Ashokkumar Subramani | G18: 46054 | H18: 46081 | I18: 100 | J18: =NETWORKDAYS(G18,H18)*I18% -> 20 | K18: =J18-COUNTIF(V18:AW18,"L")-COUNTIF(V18:AW18,"H")-COUNTIF(V18:AW18,"HDL")/2-COUNTIF(V18:AW18,"NB") -> 19 | M18: =SUM(K18:L18) -> 19 | O18: =K18-N18 -> 19 | P18: =J18-K18 -> 1 | Q18: =COUNTIF(W18:BF18,"L")+COUNTIF(W18:BF18,"HDL")/2 -> 1 | S18: Yes | T18: NO | U18: No | AL18: L
B19: F07471 | C19: Avinash . | G19: 46054 | H19: 46081 | I19: 100 | J19: =NETWORKDAYS(G19,H19)*I19% -> 20 | K19: =J19-COUNTIF(V19:AW19,"L")-COUNTIF(V19:AW19,"H")-COUNTIF(V19:AW19,"HDL")/2-COUNTIF(V19:AW19,"NB") -> 19 | M19: =SUM(K19:L19) -> 19 | O19: =K19-N19 -> 19 | P19: =J19-K19 -> 1 | Q19: =COUNTIF(W19:BF19,"L")+COUNTIF(W19:BF19,"HDL")/2 -> 1 | S19: Yes | T19: NO | U19: Yes | AT19: L
B20: F17726 | C20: Bhanu Priya | G20: 46054 | H20: 46081 | I20: 100 | J20: =NETWORKDAYS(G20,H20)*I20% -> 20 | K20: =J20-COUNTIF(V20:AW20,"L")-COUNTIF(V20:AW20,"H")-COUNTIF(V20:AW20,"HDL")/2-COUNTIF(V20:AW20,"NB") -> 12 | M20: =SUM(K20:L20) -> 12 | O20: =K20-N20 -> 12 | P20: =J20-K20 -> 8 | Q20: =COUNTIF(W20:BF20,"L")+COUNTIF(W20:BF20,"HDL")/2 -> 8 | R20: Personal Emergency leave for 5 days | S20: Yes | T20: NO | U20: No | W20: L | AK20: L | AL20: L | AR20: L | AS20: L | AT20: L | AU20: L | AV20: L
B21: F05022 | C21: Chaitanya Deepak | G21: 46054 | H21: 46081 | I21: 100 | J21: =NETWORKDAYS(G21,H21)*I21% -> 20 | K21: =J21-COUNTIF(V21:AW21,"L")-COUNTIF(V21:AW21,"H")-COUNTIF(V21:AW21,"HDL")/2-COUNTIF(V21:AW21,"NB") -> 19 | M21: =SUM(K21:L21) -> 19 | O21: =K21-N21 -> 19 | P21: =J21-K21 -> 1 | Q21: =COUNTIF(W21:BF21,"L")+COUNTIF(W21:BF21,"HDL")/2 -> 1 | S21: Yes | T21: Yes | U21: Yes | Y21: L
B22: F14094 | C22: Gokul Vasanth Susindran | G22: 46054 | H22: 46081 | I22: 100 | J22: =NETWORKDAYS(G22,H22)*I22% -> 20 | K22: =J22-COUNTIF(V22:AW22,"L")-COUNTIF(V22:AW22,"H")-COUNTIF(V22:AW22,"HDL")/2-COUNTIF(V22:AW22,"NB") -> 19 | M22: =SUM(K22:L22) -> 19 | O22: =K22-N22 -> 19 | P22: =J22-K22 -> 1 | Q22: =COUNTIF(W22:BF22,"L")+COUNTIF(W22:BF22,"HDL")/2 -> 1 | S22: Yes | T22: Yes | U22: Yes | W22: L
B23: F09402 | C23: Gowtham G | G23: 46054 | H23: 46081 | I23: 100 | J23: =NETWORKDAYS(G23,H23)*I23% -> 20 | K23: =J23-COUNTIF(V23:AW23,"L")-COUNTIF(V23:AW23,"H")-COUNTIF(V23:AW23,"HDL")/2-COUNTIF(V23:AW23,"NB") -> 17 | M23: =SUM(K23:L23) -> 17 | O23: =K23-N23 -> 17 | P23: =J23-K23 -> 3 | Q23: =COUNTIF(W23:BF23,"L")+COUNTIF(W23:BF23,"HDL")/2 -> 3 | S23: Yes | T23: NO | U23: No | Y23: L | Z23: L | AK23: L
B24: F08055 | C24: K Deepak | G24: 46054 | H24: 46081 | I24: 100 | J24: =NETWORKDAYS(G24,H24)*I24% -> 20 | K24: =J24-COUNTIF(V24:AW24,"L")-COUNTIF(V24:AW24,"H")-COUNTIF(V24:AW24,"HDL")/2-COUNTIF(V24:AW24,"NB") -> 18 | M24: =SUM(K24:L24) -> 18 | O24: =K24-N24 -> 18 | P24: =J24-K24 -> 2 | Q24: =COUNTIF(W24:BF24,"L")+COUNTIF(W24:BF24,"HDL")/2 -> 2 | S24: Yes | T24: Yes | U24: Yes | W24: L | X24: L
B25: F13133 | C25: Kartikey Rai | G25: 46054 | H25: 46081 | I25: 100 | J25: =NETWORKDAYS(G25,H25)*I25% -> 20 | K25: =J25-COUNTIF(V25:AW25,"L")-COUNTIF(V25:AW25,"H")-COUNTIF(V25:AW25,"HDL")/2-COUNTIF(V25:AW25,"NB") -> 11 | M25: =SUM(K25:L25) -> 11 | O25: =K25-N25 -> 11 | P25: =J25-K25 -> 9 | Q25: =COUNTIF(W25:BF25,"L")+COUNTIF(W25:BF25,"HDL")/2 -> 2 | R25: Allocated to the project and started working from 11th Feb, hence marked as NB. | S25: Yes | T25: Yes | U25: No | W25: NB | X25: NB | Y25: NB | Z25: NB | AA25: NB | AD25: NB | AE25: NB | AT25: L | AU25: L
B26: F15951 | C26: Kesani Srichandana | G26: 46054 | H26: 46081 | I26: 100 | J26: =NETWORKDAYS(G26,H26)*I26% -> 20 | K26: =J26-COUNTIF(V26:AW26,"L")-COUNTIF(V26:AW26,"H")-COUNTIF(V26:AW26,"HDL")/2-COUNTIF(V26:AW26,"NB") -> 20 | M26: =SUM(K26:L26) -> 20 | O26: =K26-N26 -> 20 | P26: =J26-K26 -> 0 | Q26: =COUNTIF(W26:BF26,"L")+COUNTIF(W26:BF26,"HDL")/2 -> 0 | S26: Yes | T26: NO | U26: No
B27: F16291 | C27: Khasim Pannegatla | G27: 46054 | H27: 46081 | I27: 100 | J27: =NETWORKDAYS(G27,H27)*I27% -> 20 | K27: =J27-COUNTIF(V27:AW27,"L")-COUNTIF(V27:AW27,"H")-COUNTIF(V27:AW27,"HDL")/2-COUNTIF(V27:AW27,"NB") -> 19 | M27: =SUM(K27:L27) -> 19 | O27: =K27-N27 -> 19 | P27: =J27-K27 -> 1 | Q27: =COUNTIF(W27:BF27,"L")+COUNTIF(W27:BF27,"HDL")/2 -> 1 | S27: Yes | T27: Yes | U27: Yes | AL27: L
B28: F16247 | C28: Kiran Mai P | G28: 46054 | H28: 46081 | I28: 100 | J28: =NETWORKDAYS(G28,H28)*I28% -> 20 | K28: =J28-COUNTIF(V28:AW28,"L")-COUNTIF(V28:AW28,"H")-COUNTIF(V28:AW28,"HDL")/2-COUNTIF(V28:AW28,"NB") -> 19 | M28: =SUM(K28:L28) -> 19 | O28: =K28-N28 -> 19 | P28: =J28-K28 -> 1 | Q28: =COUNTIF(W28:BF28,"L")+COUNTIF(W28:BF28,"HDL")/2 -> 1 | S28: Yes | T28: NO | U28: No | AN28: L
B29: F12415 | C29: Kunal Kumar | G29: 46054 | H29: 46081 | I29: 100 | J29: =NETWORKDAYS(G29,H29)*I29% -> 20 | K29: =J29-COUNTIF(V29:AW29,"L")-COUNTIF(V29:AW29,"H")-COUNTIF(V29:AW29,"HDL")/2-COUNTIF(V29:AW29,"NB") -> 20 | M29: =SUM(K29:L29) -> 20 | O29: =K29-N29 -> 20 | P29: =J29-K29 -> 0 | Q29: =COUNTIF(W29:BF29,"L")+COUNTIF(W29:BF29,"HDL")/2 -> 0 | S29: Yes | T29: Yes | U29: Yes
B30: F12766 | C30: Madhavi Latha Kotturu | G30: 46054 | H30: 46081 | I30: 100 | J30: =NETWORKDAYS(G30,H30)*I30% -> 20 | K30: =J30-COUNTIF(V30:AW30,"L")-COUNTIF(V30:AW30,"H")-COUNTIF(V30:AW30,"HDL")/2-COUNTIF(V30:AW30,"NB") -> 19 | M30: =SUM(K30:L30) -> 19 | O30: =K30-N30 -> 19 | P30: =J30-K30 -> 1 | Q30: =COUNTIF(W30:BF30,"L")+COUNTIF(W30:BF30,"HDL")/2 -> 1 | S30: Yes | T30: yes | U30: yes | AM30: L
B31: F06490 | C31: Mahamad Asif | G31: 46054 | H31: 46081 | I31: 100 | J31: =NETWORKDAYS(G31,H31)*I31% -> 20 | K31: =J31-COUNTIF(V31:AW31,"L")-COUNTIF(V31:AW31,"H")-COUNTIF(V31:AW31,"HDL")/2-COUNTIF(V31:AW31,"NB") -> 20 | M31: =SUM(K31:L31) -> 20 | O31: =K31-N31 -> 20 | P31: =J31-K31 -> 0 | Q31: =COUNTIF(W31:BF31,"L")+COUNTIF(W31:BF31,"HDL")/2 -> 0 | S31: Yes | T31: Yes | U31: Yes
B32: F16307 | C32: Mallik Saptarshi Thakur | G32: 46054 | H32: 46057 | I32: 100 | J32: =NETWORKDAYS(G32,H32)*I32% -> 3 | K32: =J32-COUNTIF(V32:AW32,"L")-COUNTIF(V32:AW32,"H")-COUNTIF(V32:AW32,"HDL")/2-COUNTIF(V32:AW32,"NB") -> 3 | M32: =SUM(K32:L32) -> 3 | O32: =K32-N32 -> 3 | P32: =J32-K32 -> 0 | Q32: =COUNTIF(W32:BF32,"L")+COUNTIF(W32:BF32,"HDL")/2 -> 0 | R32: Exit | S32: Yes | T32: NO | U32: No
B33: F14195 | C33: Manish Khare | G33: 46054 | H33: 46081 | I33: 100 | J33: =NETWORKDAYS(G33,H33)*I33% -> 20 | K33: =J33-COUNTIF(V33:AW33,"L")-COUNTIF(V33:AW33,"H")-COUNTIF(V33:AW33,"HDL")/2-COUNTIF(V33:AW33,"NB") -> 20 | M33: =SUM(K33:L33) -> 20 | O33: =K33-N33 -> 20 | P33: =J33-K33 -> 0 | Q33: =COUNTIF(W33:BF33,"L")+COUNTIF(W33:BF33,"HDL")/2 -> 0 | S33: Yes | T33: NO | U33: No
B34: F16444 | C34: Manish Rajesh Sharma | G34: 46054 | H34: 46081 | I34: 100 | J34: =NETWORKDAYS(G34,H34)*I34% -> 20 | K34: =J34-COUNTIF(V34:AW34,"L")-COUNTIF(V34:AW34,"H")-COUNTIF(V34:AW34,"HDL")/2-COUNTIF(V34:AW34,"NB") -> 19 | M34: =SUM(K34:L34) -> 19 | O34: =K34-N34 -> 19 | P34: =J34-K34 -> 1 | Q34: =COUNTIF(W34:BF34,"L")+COUNTIF(W34:BF34,"HDL")/2 -> 1 | S34: Yes | T34: NO | U34: Yes | AK34: L
B35: F13899 | C35: Muhammed Suhail E K | G35: 46054 | H35: 46081 | I35: 100 | J35: =NETWORKDAYS(G35,H35)*I35% -> 20 | K35: =J35-COUNTIF(V35:AW35,"L")-COUNTIF(V35:AW35,"H")-COUNTIF(V35:AW35,"HDL")/2-COUNTIF(V35:AW35,"NB") -> 20 | M35: =SUM(K35:L35) -> 20 | O35: =K35-N35 -> 20 | P35: =J35-K35 -> 0 | Q35: =COUNTIF(W35:BF35,"L")+COUNTIF(W35:BF35,"HDL")/2 -> 0 | S35: Yes | T35: Yes | U35: No
B36: F13753 | C36: Nagarjun K | G36: 46054 | H36: 46081 | I36: 100 | J36: =NETWORKDAYS(G36,H36)*I36% -> 20 | K36: =J36-COUNTIF(V36:AW36,"L")-COUNTIF(V36:AW36,"H")-COUNTIF(V36:AW36,"HDL")/2-COUNTIF(V36:AW36,"NB") -> 18 | M36: =SUM(K36:L36) -> 18 | O36: =K36-N36 -> 18 | P36: =J36-K36 -> 2 | Q36: =COUNTIF(W36:BF36,"L")+COUNTIF(W36:BF36,"HDL")/2 -> 2 | S36: Yes | T36: NO | U36: Yes | AG36: L | AH36: L
B37: F14646 | C37: Nihar Bastia | G37: 46054 | H37: 46081 | I37: 100 | J37: =NETWORKDAYS(G37,H37)*I37% -> 20 | K37: =J37-COUNTIF(V37:AW37,"L")-COUNTIF(V37:AW37,"H")-COUNTIF(V37:AW37,"HDL")/2-COUNTIF(V37:AW37,"NB") -> 19 | M37: =SUM(K37:L37) -> 19 | O37: =K37-N37 -> 19 | P37: =J37-K37 -> 1 | Q37: =COUNTIF(W37:BF37,"L")+COUNTIF(W37:BF37,"HDL")/2 -> 1 | S37: Yes | T37: Yes | U37: Yes | AA37: L
B38: F11421 | C38: Pavan Kumar Reddy Tondapu | G38: 46054 | H38: 46081 | I38: 100 | J38: =NETWORKDAYS(G38,H38)*I38% -> 20 | K38: =J38-COUNTIF(V38:AW38,"L")-COUNTIF(V38:AW38,"H")-COUNTIF(V38:AW38,"HDL")/2-COUNTIF(V38:AW38,"NB") -> 20 | M38: =SUM(K38:L38) -> 20 | O38: =K38-N38 -> 20 | P38: =J38-K38 -> 0 | Q38: =COUNTIF(W38:BF38,"L")+COUNTIF(W38:BF38,"HDL")/2 -> 0 | S38: Yes | T38: NO | U38: No
B39: F09792 | C39: Pinninti Ravindra | G39: 46054 | H39: 46081 | I39: 100 | J39: =NETWORKDAYS(G39,H39)*I39% -> 20 | K39: =J39-COUNTIF(V39:AW39,"L")-COUNTIF(V39:AW39,"H")-COUNTIF(V39:AW39,"HDL")/2-COUNTIF(V39:AW39,"NB") -> 18 | M39: =SUM(K39:L39) -> 18 | O39: =K39-N39 -> 18 | P39: =J39-K39 -> 2 | Q39: =COUNTIF(W39:BF39,"L")+COUNTIF(W39:BF39,"HDL")/2 -> 2 | S39: Yes | T39: NO | U39: No | Y39: L | AR39: L
B40: F15834 | C40: Prajwal Athrey | G40: 46054 | H40: 46081 | I40: 100 | J40: =NETWORKDAYS(G40,H40)*I40% -> 20 | K40: =J40-COUNTIF(V40:AW40,"L")-COUNTIF(V40:AW40,"H")-COUNTIF(V40:AW40,"HDL")/2-COUNTIF(V40:AW40,"NB") -> 20 | M40: =SUM(K40:L40) -> 20 | O40: =K40-N40 -> 20 | P40: =J40-K40 -> 0 | Q40: =COUNTIF(W40:BF40,"L")+COUNTIF(W40:BF40,"HDL")/2 -> 0 | S40: Yes | T40: Yes | U40: Yes
...

Sheet Sheet1
K1: check
A2: F02721 | B2: Ratul Ramchandani | H2: F10572 | I2: Aakash Arora | K2: =VLOOKUP(H2,A:A,1,0) -> F10572
A3: F05022 | B3: Chaitanya Deepak | H3: F12020 | I3: Aashish Kaushik | K3: =VLOOKUP(H3,A:A,1,0) -> F12020
A4: F06490 | B4: Mahamad Asif | H4: F16244 | I4: Abhishek Kumar | K4: =VLOOKUP(H4,A:A,1,0) -> F16244
A5: F07286 | B5: Sushanth S | H5: F17557 | I5: Adithya Udupa | K5: =VLOOKUP(H5,A:A,1,0) -> F17557
A6: F07471 | B6: Avinash . | H6: F13935 | I6: Akash Badarinath | K6: =VLOOKUP(H6,A:A,1,0) -> F13935
A7: F07920 | B7: Arjit Sharma | H7: F15043 | I7: Akash Srivastava | K7: =VLOOKUP(H7,A:A,1,0) -> F15043
A8: F08055 | B8: K Deepak | H8: F15089 | I8: Amal K | K8: =VLOOKUP(H8,A:A,1,0) -> #N/A
A9: F08227 | B9: Shubham Bhaskar | H9: F15418 | I9: Ankit . | K9: =VLOOKUP(H9,A:A,1,0) -> F15418
A10: F08462 | B10: Ashokkumar Subramani | H10: F15194 | I10: Ankit Khandelwal | K10: =VLOOKUP(H10,A:A,1,0) -> F15194
A11: F08818 | B11: Satheesh Kumar Kaliappan | H11: F16266 | I11: Anupam Kumar Tiwari | K11: =VLOOKUP(H11,A:A,1,0) -> F16266
A12: F09402 | B12: Gowtham G | H12: F17311 | I12: Arbaz Ur Rehman Khan | K12: =VLOOKUP(H12,A:A,1,0) -> F17311
A13: F09515 | B13: Roshan Raghavendra Srinivas | H13: F15984 | I13: Arindom Goswami | K13: =VLOOKUP(H13,A:A,1,0) -> F15984
... A77: F11776 | B77: Neha Agrawal | H77: F12652 | I77: Seshadri Mohana Lakshmi Sahithi | K77: =VLOOKUP(H77,A:A,1,0) -> #N/A
H78: F14503 | I78: Shivangi Khanna | K78: =VLOOKUP(H78,A:A,1,0) -> #N/A
H79: F15226 | I79: Jaiyanth RB | K79: =VLOOKUP(H79,A:A,1,0) -> F15226
H80: F16221 | I80: Dijal Tom | K80: =VLOOKUP(H80,A:A,1,0) -> F16221
H81: F17891 | I81: Hithesh G R | K81: =VLOOKUP(H81,A:A,1,0) -> F17891
H82: F17922 | I82: Sunny . | K82: =VLOOKUP(H82,A:A,1,0) -> #N/A
H83: F15815 | I83: Yashwanth S | K83: =VLOOKUP(H83,A:A,1,0) -> F15815
H84: F14764 | I84: Sourav Das | K84: =VLOOKUP(H84,A:A,1,0) -> #N/A
H85: F16824 | I85: Abhishek Kamboj | K85: =VLOOKUP(H85,A:A,1,0) -> #N/A
H86: F17876 | I86: Veeresh M | K86: =VLOOKUP(H86,A:A,1,0) -> #N/A

Sheet Mar'26
E1: To be filled by Ops PMOs only | R1: ---To be filled by Employees---
B2: 1=Working Day | G2: <------------------------------------------------------------Not to edited or changed by indiviudals---------------------------------------------------------> | R2: Reason for Non-Billing/Comments | S2: Emp to mark 'Yes' when updated this tracker | T2: Emp to mark 'Yes' when updated the Client timesheet as per this sheet | U2: Emp to mark 'Yes' when updated the Workday as per this sheet | V2: =TEXT(V3,"DDD") -> Sun | W2: =TEXT(W3,"DDD") -> Mon | X2: =TEXT(X3,"DDD") -> Tue | Y2: =TEXT(Y3,"DDD") -> Wed | Z2: =TEXT(Z3,"DDD") -> Thu | AA2: =TEXT(AA3,"DDD") -> Fri | AB2: =TEXT(AB3,"DDD") -> Sat | AC2: =TEXT(AC3,"DDD") -> Sun | ... AZ2: =TEXT(AZ3,"DDD") -> Tue
B3: Emp Id | C3: Emp Name | D3: Emp Client ID | E3: Fractal Email ID | F3: Client email ID | G3: Allocation Start Date | H3: Allocation End Date | I3: Alloc % | J3: Allocated Days | K3: Billed Days for current month | L3: Adj for past month | M3: Revenue cnf days | N3: Timesheet days | O3: Diff | P3: Unbilled Days | Q3: Total Leave Days | V3: 46082 | W3: =V3+1 -> 46083 | X3: =W3+1 -> 46084 | Y3: =X3+1 -> 46085 | Z3: =Y3+1 -> 46086 | AA3: =Z3+1 -> 46087 | AB3: =AA3+1 -> 46088 | AC3: =AB3+1 -> 46089 | AD3: =AC3+1 -> 46090 | ... AZ3: =AY3+1 -> 46112
B4: 1 | C4: =D4+1 -> 3 | D4: =B4+1 -> 2 | E4: =C4+1 -> 4 | F4: =E4+1 -> 5 | G4: =F4+1 -> 6 | H4: =G4+1 -> 7 | I4: =H4+1 -> 8 | J4: =I4+1 -> 9 | K4: =J4+1 -> 10 | L4: =K4+1 -> 11 | M4: =L4+1 -> 12 | ... P4: =O4+1 -> 15 | R4: =P4+1 -> 16 | S4: =R4+1 -> 17 | T4: =S4+1 -> 18 | U4: =T4+1 -> 19 | V4: =U4+1 -> 20 | W4: =V4+1 -> 21 | X4: =W4+1 -> 22 | Y4: =X4+1 -> 23 | Z4: =Y4+1 -> 24 | ... AZ4: =AY4+1 -> 50
B5: F10572 | C5: Aakash Arora | G5: 46082 | H5: 46112 | I5: 100 | J5: =NETWORKDAYS(G5,H5)*I5% -> 22 | K5: =J5-COUNTIF(V5:AZ5,"L")-COUNTIF(V5:AZ5,"H")-COUNTIF(V5:AZ5,"HDL")/2-COUNTIF(V5:AZ5,"NB") -> 18 | M5: =SUM(K5:L5) -> 18 | O5: =K5-N5 -> 18 | P5: =J5-K5 -> 4 | Q5: =COUNTIF(W5:BF5,"L")+COUNTIF(W5:BF5,"HDL")/2 -> 2 | S5: Yes | T5: Yes | U5: Yes | Y5: L | AD5: L | AN5: H | AO5: H
B6: F12020 | C6: Aashish Kaushik | G6: 46082 | H6: 46112 | I6: 100 | J6: =NETWORKDAYS(G6,H6)*I6% -> 22 | K6: =J6-COUNTIF(V6:AZ6,"L")-COUNTIF(V6:AZ6,"H")-COUNTIF(V6:AZ6,"HDL")/2-COUNTIF(V6:AZ6,"NB") -> 16 | M6: =SUM(K6:L6) -> 16 | O6: =K6-N6 -> 16 | P6: =J6-K6 -> 6 | Q6: =COUNTIF(W6:BF6,"L")+COUNTIF(W6:BF6,"HDL")/2 -> 4 | S6: Yes | T6: No | U6: No | AE6: L | AK6: L | AM6: L | AN6: H | AO6: H | AR6: L
B7: F16244 | C7: Abhishek Kumar | G7: 46082 | H7: 46112 | I7: 100 | J7: =NETWORKDAYS(G7,H7)*I7% -> 22 | K7: =J7-COUNTIF(V7:AZ7,"L")-COUNTIF(V7:AZ7,"H")-COUNTIF(V7:AZ7,"HDL")/2-COUNTIF(V7:AZ7,"NB") -> 16 | M7: =SUM(K7:L7) -> 16 | O7: =K7-N7 -> 16 | P7: =J7-K7 -> 6 | Q7: 4 | S7: Yes | T7: Yes | U7: Yes | AN7: H | AO7: H | AT7: L | AU7: L | AV7: L | AZ7: L
B8: F17557 | C8: Adithya Udupa | G8: 46082 | H8: 46112 | I8: 100 | J8: =NETWORKDAYS(G8,H8)*I8% -> 22 | K8: =J8-COUNTIF(V8:AZ8,"L")-COUNTIF(V8:AZ8,"H")-COUNTIF(V8:AZ8,"HDL")/2-COUNTIF(V8:AZ8,"NB") -> 17 | M8: =SUM(K8:L8) -> 17 | O8: =K8-N8 -> 17 | P8: =J8-K8 -> 5 | Q8: =COUNTIF(W8:BF8,"L")+COUNTIF(W8:BF8,"HDL")/2 -> 3 | S8: Yes | T8: No | U8: No | AA8: L | AN8: H | AO8: H | AR8: L | AS8: L
B9: F13935 | C9: Akash Badarinath | G9: 46082 | H9: 46112 | I9: 100 | J9: =NETWORKDAYS(G9,H9)*I9% -> 22 | K9: =J9-COUNTIF(V9:AZ9,"L")-COUNTIF(V9:AZ9,"H")-COUNTIF(V9:AZ9,"HDL")/2-COUNTIF(V9:AZ9,"NB") -> 17 | M9: =SUM(K9:L9) -> 17 | O9: =K9-N9 -> 17 | P9: =J9-K9 -> 5 | Q9: =COUNTIF(W9:BF9,"L")+COUNTIF(W9:BF9,"HDL")/2 -> 3 | S9: Yes | T9: Yes | U9: Yes | AK9: L | AL9: L | AM9: L | AN9: H | AO9: H
B10: F15043 | C10: Akash Srivastava | G10: 46082 | H10: 46112 | I10: 100 | J10: =NETWORKDAYS(G10,H10)*I10% -> 22 | K10: =J10-COUNTIF(V10:AZ10,"L")-COUNTIF(V10:AZ10,"H")-COUNTIF(V10:AZ10,"HDL")/2-COUNTIF(V10:AZ10,"NB") -> 19 | M10: =SUM(K10:L10) -> 19 | O10: =K10-N10 -> 19 | P10: =J10-K10 -> 3 | Q10: 1 | S10: Yes | T10: Yes | U10: Yes | Y10: L | AN10: H | AO10: H
B11: F15418 | C11: Ankit . | G11: 46082 | H11: 46112 | I11: 100 | J11: =NETWORKDAYS(G11,H11)*I11% -> 22 | K11: =J11-COUNTIF(V11:AZ11,"L")-COUNTIF(V11:AZ11,"H")-COUNTIF(V11:AZ11,"HDL")/2-COUNTIF(V11:AZ11,"NB") -> 16 | M11: =SUM(K11:L11) -> 16 | O11: =K11-N11 -> 16 | P11: =J11-K11 -> 6 | Q11: =COUNTIF(W11:BF11,"L")+COUNTIF(W11:BF11,"HDL")/2 -> 4 | S11: Yes | T11: No | U11: No | Y11: L | AL11: L | AN11: H | AO11: H | AU11: L | AV11: L
B12: F15194 | C12: Ankit Khandelwal | G12: 46082 | H12: 46112 | I12: 100 | J12: =NETWORKDAYS(G12,H12)*I12% -> 22 | K12: =J12-COUNTIF(V12:AZ12,"L")-COUNTIF(V12:AZ12,"H")-COUNTIF(V12:AZ12,"HDL")/2-COUNTIF(V12:AZ12,"NB") -> 13 | M12: =SUM(K12:L12) -> 13 | O12: =K12-N12 -> 13 | P12: =J12-K12 -> 9 | Q12: =COUNTIF(W12:BF12,"L")+COUNTIF(W12:BF12,"HDL")/2 -> 7 | S12: Yes | T12: Yes | U12: Yes | X12: L | Y12: L | Z12: L | AA12: L | AD12: L | AE12: L | AF12: L | AN12: H | AO12: H
B13: F16266 | C13: Anupam Kumar Tiwari | G13: 46082 | H13: 46112 | I13: 100 | J13: =NETWORKDAYS(G13,H13)*I13% -> 22 | K13: =J13-COUNTIF(V13:AZ13,"L")-COUNTIF(V13:AZ13,"H")-COUNTIF(V13:AZ13,"HDL")/2-COUNTIF(V13:AZ13,"NB") -> 18 | M13: =SUM(K13:L13) -> 18 | O13: =K13-N13 -> 18 | P13: =J13-K13 -> 4 | Q13: =COUNTIF(W13:BF13,"L")+COUNTIF(W13:BF13,"HDL")/2 -> 2 | S13: Yes | T13: Yes | U13: Yes | AD13: L | AE13: L | AN13: H | AO13: H
B14: F17311 | C14: Arbaz Ur Rehman Khan | G14: 46082 | H14: 46112 | I14: 100 | J14: =NETWORKDAYS(G14,H14)*I14% -> 22 | K14: =J14-COUNTIF(V14:AZ14,"L")-COUNTIF(V14:AZ14,"H")-COUNTIF(V14:AZ14,"HDL")/2-COUNTIF(V14:AZ14,"NB") -> 17 | M14: =SUM(K14:L14) -> 17 | O14: =K14-N14 -> 17 | P14: =J14-K14 -> 5 | Q14: =COUNTIF(W14:BF14,"L")+COUNTIF(W14:BF14,"HDL")/2 -> 3 | S14: Yes | T14: Yes | U14: Yes | AM14: L | AN14: H | AO14: H | AR14: L | AS14: L
B15: F15984 | C15: Arindom Goswami | G15: 46082 | H15: 46112 | I15: 100 | J15: =NETWORKDAYS(G15,H15)*I15% -> 22 | K15: =J15-COUNTIF(V15:AZ15,"L")-COUNTIF(V15:AZ15,"H")-COUNTIF(V15:AZ15,"HDL")/2-COUNTIF(V15:AZ15,"NB") -> 19 | M15: =SUM(K15:L15) -> 19 | O15: =K15-N15 -> 19 | P15: =J15-K15 -> 3 | Q15: =COUNTIF(W15:BF15,"L")+COUNTIF(W15:BF15,"HDL")/2 -> 1 | S15: Yes | T15: Yes | U15: Yes | AD15: L | AN15: H | AO15: H
B16: F07920 | C16: Arjit Sharma | G16: 46082 | H16: 46112 | I16: 100 | J16: =NETWORKDAYS(G16,H16)*I16% -> 22 | K16: =J16-COUNTIF(V16:AZ16,"L")-COUNTIF(V16:AZ16,"H")-COUNTIF(V16:AZ16,"HDL")/2-COUNTIF(V16:AZ16,"NB") -> 20 | M16: =SUM(K16:L16) -> 20 | O16: =K16-N16 -> 20 | P16: =J16-K16 -> 2 | Q16: =COUNTIF(W16:BF16,"L")+COUNTIF(W16:BF16,"HDL")/2 -> 0 | S16: Yes | T16: Yes | U16: Yes | AN16: H | AO16: H
B17: F08462 | C17: Ashokkumar Subramani | G17: 46082 | H17: 46112 | I17: 100 | J17: =NETWORKDAYS(G17,H17)*I17% -> 22 | K17: =J17-COUNTIF(V17:AZ17,"L")-COUNTIF(V17:AZ17,"H")-COUNTIF(V17:AZ17,"HDL")/2-COUNTIF(V17:AZ17,"NB") -> 11 | L17: w | M17: =SUM(K17:L17) -> 11 | O17: =K17-N17 -> 11 | P17: =J17-K17 -> 11 | Q17: =COUNTIF(W17:BF17,"L")+COUNTIF(W17:BF17,"HDL")/2 -> 9 | S17: Yes | T17: Yes | U17: Yes | Y17: L | AF17: L | AG17: L | AH17: L | AK17: L | AL17: L | AM17: L | AN17: H | AO17: H | AR17: L | AS17: L
B18: F07471 | C18: Avinash . | G18: 46082 | H18: 46112 | I18: 100 | J18: =NETWORKDAYS(G18,H18)*I18% -> 22 | K18: =J18-COUNTIF(V18:AZ18,"L")-COUNTIF(V18:AZ18,"H")-COUNTIF(V18:AZ18,"HDL")/2-COUNTIF(V18:AZ18,"NB") -> 20 | M18: =SUM(K18:L18) -> 20 | O18: =K18-N18 -> 20 | P18: =J18-K18 -> 2 | Q18: =COUNTIF(W18:BF18,"L")+COUNTIF(W18:BF18,"HDL")/2 -> 0 | S18: Yes | T18: Yes | U18: Yes | AN18: H | AO18: H
B19: F17726 | C19: Bhanu Priya | G19: 46082 | H19: 46112 | I19: 100 | J19: =NETWORKDAYS(G19,H19)*I19% -> 22 | K19: =J19-COUNTIF(V19:AZ19,"L")-COUNTIF(V19:AZ19,"H")-COUNTIF(V19:AZ19,"HDL")/2-COUNTIF(V19:AZ19,"NB") -> 20 | M19: =SUM(K19:L19) -> 20 | O19: =K19-N19 -> 20 | P19: =J19-K19 -> 2 | Q19: =COUNTIF(W19:BF19,"L")+COUNTIF(W19:BF19,"HDL")/2 -> 0 | S19: Yes | T19: No | U19: No | AN19: H | AO19: H
B20: F05022 | C20: Chaitanya Deepak | G20: 46082 | H20: 46112 | I20: 100 | J20: =NETWORKDAYS(G20,H20)*I20% -> 22 | K20: =J20-COUNTIF(V20:AZ20,"L")-COUNTIF(V20:AZ20,"H")-COUNTIF(V20:AZ20,"HDL")/2-COUNTIF(V20:AZ20,"NB") -> 15 | M20: =SUM(K20:L20) -> 15 | O20: =K20-N20 -> 15 | P20: =J20-K20 -> 7 | Q20: =COUNTIF(W20:BF20,"L")+COUNTIF(W20:BF20,"HDL")/2 -> 5 | S20: Yes | T20: Yes | U20: Yes | AD20: L | AN20: H | AO20: H | AR20: L | AV20: L | AY20: L | AZ20: L
B21: F14094 | C21: Gokul Vasanth Susindran | G21: 46082 | H21: 46112 | I21: 100 | J21: =NETWORKDAYS(G21,H21)*I21% -> 22 | K21: =J21-COUNTIF(V21:AZ21,"L")-COUNTIF(V21:AZ21,"H")-COUNTIF(V21:AZ21,"HDL")/2-COUNTIF(V21:AZ21,"NB") -> 19 | M21: =SUM(K21:L21) -> 19 | O21: =K21-N21 -> 19 | P21: =J21-K21 -> 3 | Q21: =COUNTIF(W21:BF21,"L")+COUNTIF(W21:BF21,"HDL")/2 -> 1 | S21: Yes | T21: Yes | U21: Yes | AH21: L | AN21: H | AO21: H
B22: F09402 | C22: Gowtham G | G22: 46082 | H22: 46112 | I22: 100 | J22: =NETWORKDAYS(G22,H22)*I22% -> 22 | K22: =J22-COUNTIF(V22:AZ22,"L")-COUNTIF(V22:AZ22,"H")-COUNTIF(V22:AZ22,"HDL")/2-COUNTIF(V22:AZ22,"NB") -> 20 | M22: =SUM(K22:L22) -> 20 | O22: =K22-N22 -> 20 | P22: =J22-K22 -> 2 | Q22: =COUNTIF(W22:BF22,"L")+COUNTIF(W22:BF22,"HDL")/2 -> 0 | S22: Yes | T22: No | U22: No | AN22: H | AO22: H
B23: F08055 | C23: K Deepak | G23: 46082 | H23: 46112 | I23: 100 | J23: =NETWORKDAYS(G23,H23)*I23% -> 22 | K23: =J23-COUNTIF(V23:AZ23,"L")-COUNTIF(V23:AZ23,"H")-COUNTIF(V23:AZ23,"HDL")/2-COUNTIF(V23:AZ23,"NB") -> 20 | M23: =SUM(K23:L23) -> 20 | O23: =K23-N23 -> 20 | P23: =J23-K23 -> 2 | Q23: =COUNTIF(W23:BF23,"L")+COUNTIF(W23:BF23,"HDL")/2 -> 0 | S23: Yes | T23: Yes | U23: Yes | AN23: H | AO23: H
B24: F13133 | C24: Kartikey Rai | G24: 46082 | H24: 46112 | I24: 100 | J24: =NETWORKDAYS(G24,H24)*I24% -> 22 | K24: =J24-COUNTIF(V24:AZ24,"L")-COUNTIF(V24:AZ24,"H")-COUNTIF(V24:AZ24,"HDL")/2-COUNTIF(V24:AZ24,"NB") -> 18 | M24: =SUM(K24:L24) -> 18 | O24: =K24-N24 -> 18 | P24: =J24-K24 -> 4 | Q24: =COUNTIF(W24:BF24,"L")+COUNTIF(W24:BF24,"HDL")/2 -> 2 | S24: Yes | T24: Yes | U24: Yes | AN24: H | AO24: H | AU24: L | AV24: L
B25: F15951 | C25: Kesani Srichandana | G25: 46082 | H25: 46112 | I25: 100 | J25: =NETWORKDAYS(G25,H25)*I25% -> 22 | K25: =J25-COUNTIF(V25:AZ25,"L")-COUNTIF(V25:AZ25,"H")-COUNTIF(V25:AZ25,"HDL")/2-COUNTIF(V25:AZ25,"NB") -> 20 | M25: =SUM(K25:L25) -> 20 | O25: =K25-N25 -> 20 | P25: =J25-K25 -> 2 | Q25: =COUNTIF(W25:BF25,"L")+COUNTIF(W25:BF25,"HDL")/2 -> 0 | S25: Yes | T25: No | U25: Yes | AN25: H | AO25: H
B26: F16291 | C26: Khasim Pannegatla | G26: 46082 | H26: 46112 | I26: 100 | J26: =NETWORKDAYS(G26,H26)*I26% -> 22 | K26: =J26-COUNTIF(V26:AZ26,"L")-COUNTIF(V26:AZ26,"H")-COUNTIF(V26:AZ26,"HDL")/2-COUNTIF(V26:AZ26,"NB") -> 19 | M26: =SUM(K26:L26) -> 19 | O26: =K26-N26 -> 19 | P26: =J26-K26 -> 3 | Q26: =COUNTIF(W26:BF26,"L")+COUNTIF(W26:BF26,"HDL")/2 -> 1 | S26: Yes | T26: Yes | U26: Yes | AM26: L | AN26: H | AO26: H
B27: F16247 | C27: Kiran Mai P | G27: 46082 | H27: 46112 | I27: 100 | J27: =NETWORKDAYS(G27,H27)*I27% -> 22 | K27: =J27-COUNTIF(V27:AZ27,"L")-COUNTIF(V27:AZ27,"H")-COUNTIF(V27:AZ27,"HDL")/2-COUNTIF(V27:AZ27,"NB") -> 19 | M27: =SUM(K27:L27) -> 19 | O27: =K27-N27 -> 19 | P27: =J27-K27 -> 3 | Q27: =COUNTIF(W27:BF27,"L")+COUNTIF(W27:BF27,"HDL")/2 -> 1 | S27: Yes | T27: No | U27: yes | AK27: L | AN27: H | AO27: H
B28: F12415 | C28: Kunal Kumar | G28: 46082 | H28: 46112 | I28: 100 | J28: =NETWORKDAYS(G28,H28)*I28% -> 22 | K28: =J28-COUNTIF(V28:AZ28,"L")-COUNTIF(V28:AZ28,"H")-COUNTIF(V28:AZ28,"HDL")/2-COUNTIF(V28:AZ28,"NB") -> 20 | M28: =SUM(K28:L28) -> 20 | O28: =K28-N28 -> 20 | P28: =J28-K28 -> 2 | Q28: =COUNTIF(W28:BF28,"L")+COUNTIF(W28:BF28,"HDL")/2 -> 0 | S28: Yes | T28: Yes | U28: Yes | AN28: H | AO28: H
B29: F12766 | C29: Madhavi Latha Kotturu | G29: 46082 | H29: 46112 | I29: 100 | J29: =NETWORKDAYS(G29,H29)*I29% -> 22 | K29: =J29-COUNTIF(V29:AZ29,"L")-COUNTIF(V29:AZ29,"H")-COUNTIF(V29:AZ29,"HDL")/2-COUNTIF(V29:AZ29,"NB") -> 15 | M29: =SUM(K29:L29) -> 15 | O29: =K29-N29 -> 15 | P29: =J29-K29 -> 7 | Q29: =COUNTIF(W29:BF29,"L")+COUNTIF(W29:BF29,"HDL")/2 -> 5 | S29: Yes | T29: yes | U29: Yes | AG29: L | AH29: L | AK29: L | AL29: L | AM29: L | AN29: H | AO29: H
B30: F06490 | C30: Mahamad Asif | G30: 46082 | H30: 46112 | I30: 100 | J30: =NETWORKDAYS(G30,H30)*I30% -> 22 | K30: =J30-COUNTIF(V30:AZ30,"L")-COUNTIF(V30:AZ30,"H")-COUNTIF(V30:AZ30,"HDL")/2-COUNTIF(V30:AZ30,"NB") -> 17 | M30: =SUM(K30:L30) -> 17 | O30: =K30-N30 -> 17 | P30: =J30-K30 -> 5 | Q30: =COUNTIF(W30:BF30,"L")+COUNTIF(W30:BF30,"HDL")/2 -> 3 | S30: Yes | T30: Yes | U30: Yes | AK30: L | AL30: L | AM30: L | AN30: H | AO30: H
B31: F14195 | C31: Manish Khare | G31: 46082 | H31: 46112 | I31: 100 | J31: =NETWORKDAYS(G31,H31)*I31% -> 22 | K31: =J31-COUNTIF(V31:AZ31,"L")-COUNTIF(V31:AZ31,"H")-COUNTIF(V31:AZ31,"HDL")/2-COUNTIF(V31:AZ31,"NB") -> 20 | M31: =SUM(K31:L31) -> 20 | O31: =K31-N31 -> 20 | P31: =J31-K31 -> 2 | Q31: =COUNTIF(W31:BF31,"L")+COUNTIF(W31:BF31,"HDL")/2 -> 0 | S31: Yes | T31: Yes | U31: yes | AN31: H | AO31: H
B32: F16444 | C32: Manish Rajesh Sharma | G32: 46082 | H32: 46112 | I32: 100 | J32: =NETWORKDAYS(G32,H32)*I32% -> 22 | K32: =J32-COUNTIF(V32:AZ32,"L")-COUNTIF(V32:AZ32,"H")-COUNTIF(V32:AZ32,"HDL")/2-COUNTIF(V32:AZ32,"NB") -> 18 | M32: =SUM(K32:L32) -> 18 | O32: =K32-N32 -> 18 | P32: =J32-K32 -> 4 | Q32: =COUNTIF(W32:BF32,"L")+COUNTIF(W32:BF32,"HDL")/2 -> 2 | S32: Yes | T32: Yes | U32: Yes | AK32: L | AM32: L | AN32: H | AO32: H
B33: F13899 | C33: Muhammed Suhail E K | G33: 46082 | H33: 46112 | I33: 100 | J33: =NETWORKDAYS(G33,H33)*I33% -> 22 | K33: =J33-COUNTIF(V33:AZ33,"L")-COUNTIF(V33:AZ33,"H")-COUNTIF(V33:AZ33,"HDL")/2-COUNTIF(V33:AZ33,"NB") -> 20 | M33: =SUM(K33:L33) -> 20 | O33: =K33-N33 -> 20 | P33: =J33-K33 -> 2 | Q33: =COUNTIF(W33:BF33,"L")+COUNTIF(W33:BF33,"HDL")/2 -> 0 | S33: Yes | T33: No | U33: No | AN33: H | AO33: H
B34: F13753 | C34: Nagarjun K | G34: 46082 | H34: 46112 | I34: 100 | J34: =NETWORKDAYS(G34,H34)*I34% -> 22 | K34: =J34-COUNTIF(V34:AZ34,"L")-COUNTIF(V34:AZ34,"H")-COUNTIF(V34:AZ34,"HDL")/2-COUNTIF(V34:AZ34,"NB") -> 20 | M34: =SUM(K34:L34) -> 20 | O34: =K34-N34 -> 20 | P34: =J34-K34 -> 2 | Q34: =COUNTIF(W34:BF34,"L")+COUNTIF(W34:BF34,"HDL")/2 -> 0 | S34: Yes | T34: No | U34: No | AN34: H | AO34: H
B35: F14646 | C35: Nihar Bastia | G35: 46082 | H35: 46112 | I35: 100 | J35: =NETWORKDAYS(G35,H35)*I35% -> 22 | K35: =J35-COUNTIF(V35:AZ35,"L")-COUNTIF(V35:AZ35,"H")-COUNTIF(V35:AZ35,"HDL")/2-COUNTIF(V35:AZ35,"NB") -> 19 | M35: =SUM(K35:L35) -> 19 | O35: =K35-N35 -> 19 | P35: =J35-K35 -> 3 | Q35: =COUNTIF(W35:BF35,"L")+COUNTIF(W35:BF35,"HDL")/2 -> 1 | S35: Yes | T35: Yes | U35: Yes | Y35: L | AN35: H | AO35: H
B36: F11421 | C36: Pavan Kumar Reddy Tondapu | G36: 46082 | H36: 46112 | I36: 100 | J36: =NETWORKDAYS(G36,H36)*I36% -> 22 | K36: =J36-COUNTIF(V36:AZ36,"L")-COUNTIF(V36:AZ36,"H")-COUNTIF(V36:AZ36,"HDL")/2-COUNTIF(V36:AZ36,"NB") -> 20 | M36: =SUM(K36:L36) -> 20 | O36: =K36-N36 -> 20 | P36: =J36-K36 -> 2 | Q36: =COUNTIF(W36:BF36,"L")+COUNTIF(W36:BF36,"HDL")/2 -> 0 | S36: Yes | T36: No | U36: Yes | AN36: H | AO36: H
B37: F09792 | C37: Pinninti Ravindra | G37: 46082 | H37: 46112 | I37: 100 | J37: =NETWORKDAYS(G37,H37)*I37% -> 22 | K37: =J37-COUNTIF(V37:AZ37,"L")-COUNTIF(V37:AZ37,"H")-COUNTIF(V37:AZ37,"HDL")/2-COUNTIF(V37:AZ37,"NB") -> 17.5 | M37: =SUM(K37:L37) -> 17.5 | O37: =K37-N37 -> 17.5 | P37: =J37-K37 -> 4.5 | Q37: =COUNTIF(W37:BF37,"L")+COUNTIF(W37:BF37,"HDL")/2 -> 2.5 | S37: Yes | T37: No | U37: No | AD37: L | AN37: H | AO37: H | AT37: L | AY37: HDL
B38: F15834 | C38: Prajwal Athrey | G38: 46082 | H38: 46112 | I38: 100 | J38: =NETWORKDAYS(G38,H38)*I38% -> 22 | K38: =J38-COUNTIF(V38:AZ38,"L")-COUNTIF(V38:AZ38,"H")-COUNTIF(V38:AZ38,"HDL")/2-COUNTIF(V38:AZ38,"NB") -> 19 | M38: =SUM(K38:L38) -> 19 | O38: =K38-N38 -> 19 | P38: =J38-K38 -> 3 | Q38: =COUNTIF(W38:BF38,"L")+COUNTIF(W38:BF38,"HDL")/2 -> 1 | S38: Yes | T38: Yes | U38: Yes | AK38: L | AN38: H | AO38: H
B39: F14085 | C39: Prakash Solanki | G39: 46082 | H39: 46112 | I39: 100 | J39: =NETWORKDAYS(G39,H39)*I39% -> 22 | K39: =J39-COUNTIF(V39:AZ39,"L")-COUNTIF(V39:AZ39,"H")-COUNTIF(V39:AZ39,"HDL")/2-COUNTIF(V39:AZ39,"NB") -> 19 | M39: =SUM(K39:L39) -> 19 | O39: =K39-N39 -> 19 | P39: =J39-K39 -> 3 | Q39: =COUNTIF(W39:BF39,"L")+COUNTIF(W39:BF39,"HDL")/2 -> 1 | S39: Yes | T39: No | U39: No | Y39: L | AN39: H | AO39: H
B40: F14985 | C40: Pranshul Gupta | G40: 46082 | H40: 46112 | I40: 100 | J40: =NETWORKDAYS(G40,H40)*I40% -> 22 | K40: =J40-COUNTIF(V40:AZ40,"L")-COUNTIF(V40:AZ40,"H")-COUNTIF(V40:AZ40,"HDL")/2-COUNTIF(V40:AZ40,"NB") -> 17 | M40: =SUM(K40:L40) -> 17 | O40: =K40-N40 -> 17 | P40: =J40-K40 -> 5 | Q40: =COUNTIF(W40:BF40,"L")+COUNTIF(W40:BF40,"HDL")/2 -> 3 | S40: Yes | T40: Yes | U40: Yes | AK40: L | AL40: L | AM40: L | AN40: H | AO40: H
...

Sheet Apr'26
E1: To be filled by Ops PMOs only | R1: ---To be filled by Employees---
B2: 1=Working Day | G2: <------------------------------------------------------------Not to edited or changed by indiviudals---------------------------------------------------------> | R2: Reason for Non-Billing/Comments | S2: Emp to mark 'Yes' when updated this tracker | T2: Emp to mark 'Yes' when updated the Client timesheet as per this sheet | U2: Emp to mark 'Yes' when updated the Workday as per this sheet | V2: =TEXT(V3,"DDD") -> Wed | W2: =TEXT(W3,"DDD") -> Thu | X2: =TEXT(X3,"DDD") -> Fri | Y2: =TEXT(Y3,"DDD") -> Sat | Z2: =TEXT(Z3,"DDD") -> Sun | AA2: =TEXT(AA3,"DDD") -> Mon | AB2: =TEXT(AB3,"DDD") -> Tue | AC2: =TEXT(AC3,"DDD") -> Wed | ... AY2: =TEXT(AY3,"DDD") -> Thu
B3: Emp Id | C3: Emp Name | D3: Emp Client ID | E3: Fractal Email ID | F3: Client email ID | G3: Allocation Start Date | H3: Allocation End Date | I3: Alloc % | J3: Allocated Days | K3: Billed Days for current month | L3: Adj for past month | M3: Revenue cnf days | N3: Timesheet days | O3: Diff | P3: Unbilled Days | Q3: Total Leave Days | V3: 46113 | W3: =V3+1 -> 46114 | X3: =W3+1 -> 46115 | Y3: =X3+1 -> 46116 | Z3: =Y3+1 -> 46117 | AA3: =Z3+1 -> 46118 | AB3: =AA3+1 -> 46119 | AC3: =AB3+1 -> 46120 | AD3: =AC3+1 -> 46121 | ... AY3: =AX3+1 -> 46142
B4: 1 | C4: =D4+1 -> 3 | D4: =B4+1 -> 2 | E4: =C4+1 -> 4 | F4: =E4+1 -> 5 | G4: =F4+1 -> 6 | H4: =G4+1 -> 7 | I4: =H4+1 -> 8 | J4: =I4+1 -> 9 | K4: =J4+1 -> 10 | L4: =K4+1 -> 11 | M4: =L4+1 -> 12 | ... P4: =O4+1 -> 15 | R4: =P4+1 -> 16 | S4: =R4+1 -> 17 | T4: =S4+1 -> 18 | U4: =T4+1 -> 19 | V4: =U4+1 -> 20 | W4: =V4+1 -> 21 | X4: =W4+1 -> 22 | Y4: =X4+1 -> 23 | Z4: =Y4+1 -> 24 | ... AY4: =AX4+1 -> 49
B5: F10572 | C5: Aakash Arora | E5: =_xlfn.XLOOKUP(B5,'[1]Employee Details Report'!$A:$A,'[1]Employee Details Report'!$C:$C,0,0,1) -> aakash.arora@fractal.ai | G5: 46113 | H5: 46142 | I5: 100 | J5: =NETWORKDAYS(G5,H5)*I5% -> 22 | K5: =J5-COUNTIF(V5:AY5,"L")-COUNTIF(V5:AY5,"H")-COUNTIF(V5:AY5,"HDL")/2-COUNTIF(V5:AY5,"NB") -> 22 | M5: =SUM(K5:L5) -> 22 | O5: =K5-N5 -> 22 | P5: =J5-K5 -> 0 | Q5: =COUNTIF(V5:BE5,"L")+COUNTIF(V5:BE5,"HDL")/2 -> 0 | S5: Yes | T5: Yes | U5: Yes
B6: F12020 | C6: Aashish Kaushik | E6: =_xlfn.XLOOKUP(B6,'[1]Employee Details Report'!$A:$A,'[1]Employee Details Report'!$C:$C,0,0,1) -> aashish.kaushik@fractal.ai | G6: 46113 | H6: 46142 | I6: 100 | J6: =NETWORKDAYS(G6,H6)*I6% -> 22 | K6: =J6-COUNTIF(V6:AY6,"L")-COUNTIF(V6:AY6,"H")-COUNTIF(V6:AY6,"HDL")/2-COUNTIF(V6:AY6,"NB") -> 20 | M6: =SUM(K6:L6) -> 20 | O6: =K6-N6 -> 20 | P6: =J6-K6 -> 2 | Q6: =COUNTIF(V6:BE6,"L")+COUNTIF(V6:BE6,"HDL")/2 -> 2 | S6: Yes | T6: No | U6: Yes | AI6: L | AJ6: L
B7: F16244 | C7: Abhishek Kumar | E7: =_xlfn.XLOOKUP(B7,'[1]Employee Details Report'!$A:$A,'[1]Employee Details Report'!$C:$C,0,0,1) -> abhishek.kumar7@fractal.ai | G7: 46113 | H7: 46142 | I7: 100 | J7: =NETWORKDAYS(G7,H7)*I7% -> 22 | K7: =J7-COUNTIF(V7:AY7,"L")-COUNTIF(V7:AY7,"H")-COUNTIF(V7:AY7,"HDL")/2-COUNTIF(V7:AY7,"NB") -> 18 | M7: =SUM(K7:L7) -> 18 | O7: =K7-N7 -> 18 | P7: 4 | Q7: 4 | S7: Yes | T7: No | U7: Yes | V7: L | W7: L | X7: L | AV7: L
B8: F17557 | C8: Adithya Udupa | E8: =_xlfn.XLOOKUP(B8,'[1]Employee Details Report'!$A:$A,'[1]Employee Details Report'!$C:$C,0,0,1) -> adithya.udupa@fractal.ai | G8: 46113 | H8: 46142 | I8: 100 | J8: =NETWORKDAYS(G8,H8)*I8% -> 22 | K8: =J8-COUNTIF(V8:AY8,"L")-COUNTIF(V8:AY8,"H")-COUNTIF(V8:AY8,"HDL")/2-COUNTIF(V8:AY8,"NB") -> 19 | M8: =SUM(K8:L8) -> 19 | O8: =K8-N8 -> 19 | P8: =J8-K8 -> 3 | Q8: =COUNTIF(V8:BE8,"L")+COUNTIF(V8:BE8,"HDL")/2 -> 3 | S8: yes | T8: No | U8: No | AQ8: L | AR8: L | AS8: L
B9: F13935 | C9: Akash Badarinath | E9: =_xlfn.XLOOKUP(B9,'[1]Employee Details Report'!$A:$A,'[1]Employee Details Report'!$C:$C,0,0,1) -> akash.badarinath@fractal.ai | G9: 46113 | H9: 46142 | I9: 100 | J9: =NETWORKDAYS(G9,H9)*I9% -> 22 | K9: =J9-COUNTIF(V9:AY9,"L")-COUNTIF(V9:AY9,"H")-COUNTIF(V9:AY9,"HDL")/2-COUNTIF(V9:AY9,"NB") -> 22 | M9: =SUM(K9:L9) -> 22 | O9: =K9-N9 -> 22 | P9: =J9-K9 -> 0 | Q9: =COUNTIF(V9:BE9,"L")+COUNTIF(V9:BE9,"HDL")/2 -> 0 | S9: Yes | T9: Yes | U9: Yes
